Workbook

Sheet Dashboard
B2: Privileged Access Review - Dashboard
B3: People, not accounts. Press F9 if calculation is set to manual.
B5: PEOPLE | C5: Value | D5: Why it matters
B6: People holding privileged access | C6: =COUNTA(People!$A$2:$A$1001) | D6: One row per human, not per account.
B7: Tier 0 in at least one plane | C7: =COUNTIF(People!$P$2:$P$1001,0) | D7: Control plane. These people can grant themselves anything else.
B8: PRIVILEGED IN MULTIPLE PLANES | C8: =COUNTIF(People!$O$2:$O$1001,"YES") | D8: The reason this workbook is person-based. Accounts never mix; the human does. Compromise reaches every plane they hold at once.
B9: Tier 0 in multiple planes | C9: =COUNTIFS(People!$O$2:$O$1001,"YES",People!$P$2:$P$1001,0) | D9: The shortest and most consequential list here.
B10: ORPHANED admin accounts | C10: =COUNTIF(People!$Q$2:$Q$1001,"YES") | D10: Enabled admin account, standard account disabled or missing. Almost always a leaver whose admin objects were missed at offboarding. Start here.
B11: AD/Entra active mismatch | C11: =COUNTIF(People!$Z$2:$Z$1001,"YES") | D11: AD is disabled but Entra is still active. Entra Connect sync is supposed to prevent this - treat it as a live access-control gap, not a review backlog item.
B12: Holding more than two admin accounts | C12: =COUNTIF(People!$R$2:$R$1001,">2") | D12: Account sprawl per individual.
B13: Not self-reviewed this cycle | C13: =COUNTIFS(People!$A$2:$A$1001,"<>",People!$AB$2:$AB$1001,"<>Yes") | D13: An access review here means the account holder confirms the access is still needed, with the decision recorded automatically. Until then this is an inventory, not a review.
B15: CLOUD ADMIN ACCOUNTS | C15: Value | D15: Why it matters
B16: Cloud admin accounts | C16: =COUNTA('Cloud Admin Accounts'!$A$2:$A$1001)
B17: ORPHANED - admin enabled, standard account disabled/missing | C17: =COUNTIF('Cloud Admin Accounts'!$T$2:$T$1001,"YES") | D17: Likely leavers. Admin accounts are separate objects and are routinely missed at offboarding.
B18: Holding NO privilege in either plane | C18: =COUNTIFS('Cloud Admin Accounts'!$K$2:$K$1001,"None",'Cloud Admin Accounts'!$L$2:$L$1001,"None") | D18: Privilege was removed and the account wasn't, or it never held any. Not on the Entra or Azure RBAC worklists below - this is the only place it's visible.
B19: Enabled without phishing-resistant MFA (Tier <=1) | C19: =COUNTIFS('Cloud Admin Accounts'!$E$2:$E$1001,"Yes",'Cloud Admin Accounts'!$I$2:$I$1001,"No",'Cloud Admin Accounts'!$M$2:$M$1001,"<=1") | D19: Push and SMS are phishable. A phished Tier 0/1 admin is a tenant compromise.
B20: Enabled with NO MFA registered | C20: =COUNTIFS('Cloud Admin Accounts'!$E$2:$E$1001,"Yes",'Cloud Admin Accounts'!$H$2:$H$1001,"No") | D20: Should be zero.
B21: Dormant 90+ days | C21: =COUNTIF('Cloud Admin Accounts'!$S$2:$S$1001,">90") | D21: Privilege or not, the account is provisioned and unused.
B23: ENTRA ADMINS | C23: Value | D23: Why it matters
B24: Accounts holding an Entra role | C24: =COUNTA('Entra Admins'!$A$2:$A$1001)
B25: Tier 0 | C25: =COUNTIF('Entra Admins'!$P$2:$P$1001,0) | D25: Global Admin, Privileged Role Admin, Application Admin, Hybrid Identity Admin and equivalents.
B26: Holding STANDING (permanent) roles | C26: =COUNTIF('Entra Admins'!$AK$2:$AK$1001,"Yes") | D26: Live every hour of every day whether in use or not. Converting these to PIM-eligible is the highest-value change available here.
B27: Tier 0 with standing roles | C27: =COUNTIFS('Entra Admins'!$P$2:$P$1001,0,'Entra Admins'!$AK$2:$AK$1001,"Yes") | D27: Permanent control-plane privilege.
B28: Privilege held via GROUP membership | C28: =COUNTIF('Entra Admins'!$U$2:$U$1001,">0") | D28: Role-assignable group membership. Any review matching only on the user object would miss these entirely.
B29: ... holding NO direct assignment | C29: =COUNTIF('Entra Admins'!$Q$2:$Q$1001,"Group only") | D29: These accounts look unprivileged on their own object. Remediation is group removal, not role removal.
B30: Roles scoped to an Administrative Unit | C30: =COUNTIFS('Entra Admins'!$V$2:$V$1001,"<>Tenant-wide",'Entra Admins'!$V$2:$V$1001,"<>") | D30: Narrower than tenant-wide. Do not treat these as full-tenant privilege.
B31: Also holds an Azure RBAC role | C31: =COUNTIF('Entra Admins'!$W$2:$W$1001,"Yes") | D31: Coordinate with whoever owns the Azure RBAC Admins tab before closing out remediation here.
B33: AZURE RBAC ADMINS | C33: Value | D33: Why it matters
B34: Accounts holding an Azure RBAC role | C34: =COUNTA('Azure RBAC Admins'!$A$2:$A$1001)
B35: Tier 0 | C35: =COUNTIF('Azure RBAC Admins'!$M$2:$M$1001,0) | D35: Owner, User Access Administrator, RBAC Administrator.
B36: Privilege held via GROUP membership | C36: =COUNTIF('Azure RBAC Admins'!$S$2:$S$1001,">0") | D36: Role-assignable group membership. Any review matching only on the user object would miss these entirely.
B37: ... holding NO direct assignment | C37: =COUNTIF('Azure RBAC Admins'!$O$2:$O$1001,"Group only") | D37: These accounts look unprivileged on their own object. Remediation is group removal, not role removal.
B38: Sub or MG scoped | C38: =COUNTIF('Azure RBAC Admins'!$N$2:$N$1001,"Yes") | D38: Assignment covers every resource in the scope, including ones created next year.
B39: Also holds an Entra role | C39: =COUNTIF('Azure RBAC Admins'!$T$2:$T$1001,"Yes") | D39: Coordinate with whoever owns the Entra Admins tab before closing out remediation here.
B41: ON-PREM ADMINS (Active Directory) | C41: Value | D41: Why it matters
B42: On-prem admin accounts | C42: =COUNTA('On-Prem Admins'!$A$2:$A$1001)
B43: Tier 0 (domain compromise capable) | C43: =COUNTIF('On-Prem Admins'!$P$2:$P$1001,0) | D43: Domain Admins, Enterprise Admins, Backup Operators, DnsAdmins and equivalents.
B44: Tier 0 without smartcard required | C44: =COUNTIFS('On-Prem Admins'!$P$2:$P$1001,0,'On-Prem Admins'!$L$2:$L$1001,"No") | D44: The on-prem equivalent of an admin without FIDO2 - a password alone protects the domain.
B45: Password older than one year | C45: =COUNTIFS('On-Prem Admins'!$J$2:$J$1001,">365",'On-Prem Admins'!$F$2:$F$1001,"Yes")
B46: PasswordNeverExpires set | C46: =COUNTIFS('On-Prem Admins'!$K$2:$K$1001,"Yes",'On-Prem Admins'!$F$2:$F$1001,"Yes")
...

Sheet How to Use
B2: Privileged Access Review - how to use this workbook
B4: This tracks PEOPLE who hold privileged access, not systems. Service accounts, service principals and managed identities belong in the Service Identity Inventory instead - the two are deliberately separate, because human privilege is reviewed by the account holder confirming their own need on a recurring cycle, while machine privilege is reviewed against a workload's function.
B6: Naming conventions
B8: Cloud admins follow username.azr@corp.onmicrosoft.com. On-prem admins follow username-a. Both encode the same base username, and that is what links an admin account back to a person. If your conventions differ, adjust the -AdminPattern and -BaseUsernameCapture parameters on the collection scripts rather than editing the workbook.
B10: Order of operations
B12: 1. Build-CloudAdminReview.ps1 -> Cloud-Admin-Accounts.csv -> 'Cloud Admin Accounts' tab, A2, columns A-R
B14: -> Entra-Admins.csv -> 'Entra Admins' tab, A2, columns A-AB
B16: -> Azure-RBAC-Admins.csv -> 'Azure RBAC Admins' tab, A2, columns A-Y
B18: 2. Build-OnPremAdminReview.ps1 -> OnPrem-Admins.csv -> 'On-Prem Admins' tab, A2, columns A-Z
B20: 3. Merge-AdminReview.ps1 -> Admin-People.csv
B22: 4. Update-AdminPeopleAD.ps1 -> Admin-People.csv -> (adds AD Manager, AD Account Active)
B24: 5. Update-AdminPeopleEntra.ps1 -> Admin-People.csv -> 'People' tab, A2, columns A-Z
... B70: For APRA-regulated entities, CPS 234 requires clearly defined information security roles and responsibilities. Attestation here is self-review with Tier 0 escalation to a second reviewer, not line-manager sign-off - check with whoever owns your CPS 234 evidence that the Access Review decision log meets their expectations before relying on it as the sole record.

Sheet People
A1: Base Username | B1: Person Display Name | C1: Department | D1: Job Title | E1: Has Cloud Admin | F1: Cloud Admin Accounts | G1: Highest Entra Role | H1: Entra Tier | I1: Highest Azure Role | J1: Azure Tier | K1: Has On-Prem Admin | L1: On-Prem Admin Accounts | M1: Highest AD Group | N1: On-Prem Tier | O1: Privileged In Multiple Planes | P1: Overall Tier | Q1: Orphaned Admin Account | R1: Total Admin Accounts | S1: On-Prem Identity Exists | T1: On-Prem Identity Enabled | U1: Cloud Identity Exists | V1: Cloud Identity Enabled | W1: AD Manager | X1: AD Account Active | Y1: Entra Account Active | Z1: AD/Entra Active Mismatch | AA1: Line Manager | AB1: Self-Reviewed (All Accounts) | AC1: Last Reviewed | AD1: Auto-Removal Risk | AE1: Notes
A2: jsmith | B2: Jane Smith | C2: Cloud Platform Engineering | D2: Principal Engineer | E2: Yes | F2: jsmith.azr@corp.onmicrosoft.com | G2: Global Administrator | H2: 0 | I2: Owner | J2: 0 | K2: Yes | L2: jsmith-a | M2: Domain Admins | N2: 0 | O2: YES | P2: 0 | Q2: No | R2: 2 | S2: Yes | T2: Yes | U2: Yes | V2: Yes | W2: atran@corp.com.au | X2: Yes | Y2: Not Checked (AD Active) | AA2: Alex Tran | AB2: No | AD2: =IF($A2="","",IF(OR($AB2<>"Yes",$AC2="",TODAY()-$AC2>90),"At Risk","Not At Risk")) | AE2: EXAMPLE ROW - delete before use. Tier 0 in all three planes.
AD3: =IF($A3="","",IF(OR($AB3<>"Yes",$AC3="",TODAY()-$AC3>90),"At Risk","Not At Risk"))
AD4: =IF($A4="","",IF(OR($AB4<>"Yes",$AC4="",TODAY()-$AC4>90),"At Risk","Not At Risk"))
AD5: =IF($A5="","",IF(OR($AB5<>"Yes",$AC5="",TODAY()-$AC5>90),"At Risk","Not At Risk"))
AD6: =IF($A6="","",IF(OR($AB6<>"Yes",$AC6="",TODAY()-$AC6>90),"At Risk","Not At Risk"))
AD7: =IF($A7="","",IF(OR($AB7<>"Yes",$AC7="",TODAY()-$AC7>90),"At Risk","Not At Risk"))
AD8: =IF($A8="","",IF(OR($AB8<>"Yes",$AC8="",TODAY()-$AC8>90),"At Risk","Not At Risk"))
AD9: =IF($A9="","",IF(OR($AB9<>"Yes",$AC9="",TODAY()-$AC9>90),"At Risk","Not At Risk"))
AD10: =IF($A10="","",IF(OR($AB10<>"Yes",$AC10="",TODAY()-$AC10>90),"At Risk","Not At Risk"))
AD11: =IF($A11="","",IF(OR($AB11<>"Yes",$AC11="",TODAY()-$AC11>90),"At Risk","Not At Risk"))
AD12: =IF($A12="","",IF(OR($AB12<>"Yes",$AC12="",TODAY()-$AC12>90),"At Risk","Not At Risk"))
AD13: =IF($A13="","",IF(OR($AB13<>"Yes",$AC13="",TODAY()-$AC13>90),"At Risk","Not At Risk"))
AD14: =IF($A14="","",IF(OR($AB14<>"Yes",$AC14="",TODAY()-$AC14>90),"At Risk","Not At Risk"))
... AD1001: =IF($A1001="","",IF(OR($AB1001<>"Yes",$AC1001="",TODAY()-$AC1001>90),"At Risk","Not At Risk"))

Sheet Cloud Admin Accounts
A1: Admin UPN | B1: Display Name | C1: Object ID | D1: Base Username | E1: Enabled | F1: Created | G1: Last Sign-In | H1: MFA Registered | I1: Phishing Resistant | J1: Auth Methods | K1: Highest Entra Role | L1: Highest Azure Role | M1: Overall Tier | N1: Standard Account UPN | O1: Standard Acct Enabled | P1: Person Display Name | Q1: Department | R1: Job Title | S1: Days Since Sign-In | T1: ORPHANED? | U1: Risk Flags
A2: jsmith.azr@corp.onmicrosoft.com | B2: Jane Smith (Cloud Admin) | C2: 4c8e1f2a-9b3d-4e6f-a1c5-7d2e8f3a9b4c | D2: jsmith | E2: Yes | F2: 45173 | G2: 46246 | H2: Yes | I2: No | J2: microsoftAuthenticatorPush; sms | K2: Global Administrator | L2: Owner | M2: 0 | N2: jsmith@corp.com.au | O2: Yes | P2: Jane Smith | Q2: Cloud Platform Engineering | R2: Principal Engineer | S2: =IF($G2="","",TODAY()-$G2) | T2: =IF($A2="","",IF(AND($E2="Yes",OR($O2="No",$O2="NOT FOUND")),"YES","")) | U2: =IF($A2="","",TRIM(IF(AND($M2=0,$I2<>"Yes"),"T0-NoPhishResistant ","")&IF($H2="No","NoMFA ","")&IF(AND($E2="Yes",$G2=""),"NeverSignedIn ","")))
S3: =IF($G3="","",TODAY()-$G3) | T3: =IF($A3="","",IF(AND($E3="Yes",OR($O3="No",$O3="NOT FOUND")),"YES","")) | U3: =IF($A3="","",TRIM(IF(AND($M3=0,$I3<>"Yes"),"T0-NoPhishResistant ","")&IF($H3="No","NoMFA ","")&IF(AND($E3="Yes",$G3=""),"NeverSignedIn ","")))
S4: =IF($G4="","",TODAY()-$G4) | T4: =IF($A4="","",IF(AND($E4="Yes",OR($O4="No",$O4="NOT FOUND")),"YES","")) | U4: =IF($A4="","",TRIM(IF(AND($M4=0,$I4<>"Yes"),"T0-NoPhishResistant ","")&IF($H4="No","NoMFA ","")&IF(AND($E4="Yes",$G4=""),"NeverSignedIn ","")))
S5: =IF($G5="","",TODAY()-$G5) | T5: =IF($A5="","",IF(AND($E5="Yes",OR($O5="No",$O5="NOT FOUND")),"YES","")) | U5: =IF($A5="","",TRIM(IF(AND($M5=0,$I5<>"Yes"),"T0-NoPhishResistant ","")&IF($H5="No","NoMFA ","")&IF(AND($E5="Yes",$G5=""),"NeverSignedIn ","")))
S6: =IF($G6="","",TODAY()-$G6) | T6: =IF($A6="","",IF(AND($E6="Yes",OR($O6="No",$O6="NOT FOUND")),"YES","")) | U6: =IF($A6="","",TRIM(IF(AND($M6=0,$I6<>"Yes"),"T0-NoPhishResistant ","")&IF($H6="No","NoMFA ","")&IF(AND($E6="Yes",$G6=""),"NeverSignedIn ","")))
S7: =IF($G7="","",TODAY()-$G7) | T7: =IF($A7="","",IF(AND($E7="Yes",OR($O7="No",$O7="NOT FOUND")),"YES","")) | U7: =IF($A7="","",TRIM(IF(AND($M7=0,$I7<>"Yes"),"T0-NoPhishResistant ","")&IF($H7="No","NoMFA ","")&IF(AND($E7="Yes",$G7=""),"NeverSignedIn ","")))
S8: =IF($G8="","",TODAY()-$G8) | T8: =IF($A8="","",IF(AND($E8="Yes",OR($O8="No",$O8="NOT FOUND")),"YES","")) | U8: =IF($A8="","",TRIM(IF(AND($M8=0,$I8<>"Yes"),"T0-NoPhishResistant ","")&IF($H8="No","NoMFA ","")&IF(AND($E8="Yes",$G8=""),"NeverSignedIn ","")))
S9: =IF($G9="","",TODAY()-$G9) | T9: =IF($A9="","",IF(AND($E9="Yes",OR($O9="No",$O9="NOT FOUND")),"YES","")) | U9: =IF($A9="","",TRIM(IF(AND($M9=0,$I9<>"Yes"),"T0-NoPhishResistant ","")&IF($H9="No","NoMFA ","")&IF(AND($E9="Yes",$G9=""),"NeverSignedIn ","")))
S10: =IF($G10="","",TODAY()-$G10) | T10: =IF($A10="","",IF(AND($E10="Yes",OR($O10="No",$O10="NOT FOUND")),"YES","")) | U10: =IF($A10="","",TRIM(IF(AND($M10=0,$I10<>"Yes"),"T0-NoPhishResistant ","")&IF($H10="No","NoMFA ","")&IF(AND($E10="Yes",$G10=""),"NeverSignedIn ","")))
S11: =IF($G11="","",TODAY()-$G11) | T11: =IF($A11="","",IF(AND($E11="Yes",OR($O11="No",$O11="NOT FOUND")),"YES","")) | U11: =IF($A11="","",TRIM(IF(AND($M11=0,$I11<>"Yes"),"T0-NoPhishResistant ","")&IF($H11="No","NoMFA ","")&IF(AND($E11="Yes",$G11=""),"NeverSignedIn ","")))
S12: =IF($G12="","",TODAY()-$G12) | T12: =IF($A12="","",IF(AND($E12="Yes",OR($O12="No",$O12="NOT FOUND")),"YES","")) | U12: =IF($A12="","",TRIM(IF(AND($M12=0,$I12<>"Yes"),"T0-NoPhishResistant ","")&IF($H12="No","NoMFA ","")&IF(AND($E12="Yes",$G12=""),"NeverSignedIn ","")))
S13: =IF($G13="","",TODAY()-$G13) | T13: =IF($A13="","",IF(AND($E13="Yes",OR($O13="No",$O13="NOT FOUND")),"YES","")) | U13: =IF($A13="","",TRIM(IF(AND($M13=0,$I13<>"Yes"),"T0-NoPhishResistant ","")&IF($H13="No","NoMFA ","")&IF(AND($E13="Yes",$G13=""),"NeverSignedIn ","")))
S14: =IF($G14="","",TODAY()-$G14) | T14: =IF($A14="","",IF(AND($E14="Yes",OR($O14="No",$O14="NOT FOUND")),"YES","")) | U14: =IF($A14="","",TRIM(IF(AND($M14=0,$I14<>"Yes"),"T0-NoPhishResistant ","")&IF($H14="No","NoMFA ","")&IF(AND($E14="Yes",$G14=""),"NeverSignedIn ","")))
... S1001: =IF($G1001="","",TODAY()-$G1001) | T1001: =IF($A1001="","",IF(AND($E1001="Yes",OR($O1001="No",$O1001="NOT FOUND")),"YES","")) | U1001: =IF($A1001="","",TRIM(IF(AND($M1001=0,$I1001<>"Yes"),"T0-NoPhishResistant ","")&IF($H1001="No","NoMFA ","")&IF(AND($E1001="Yes",$G1001=""),"NeverSignedIn ","")))

Sheet Entra Admins
A1: Admin UPN | B1: Display Name | C1: Object ID | D1: Base Username | E1: Enabled | F1: Created | G1: Last Sign-In | H1: MFA Registered | I1: Phishing Resistant | J1: Auth Methods | K1: Entra Roles (Active) | L1: Entra Roles (Eligible) | M1: Active Role Count | N1: Eligible Role Count | O1: Highest Entra Role | P1: Entra Tier | Q1: Assignment Route | R1: Granting Groups | S1: Granting Group IDs | T1: Direct Assignments | U1: Group Assignments | V1: Directory Scopes | W1: Also Holds Azure RBAC | X1: Standard Account UPN | Y1: Standard Acct Enabled | Z1: Person Display Name | AA1: Department | AB1: Job Title | AC1: Access Type | AD1: Business Justification | AE1: Decided By | AF1: Review Decision Date | AG1: Next Review Due | AH1: Last Reviewed | AI1: Review Decision | AJ1: Notes | AK1: Standing Privilege? | AL1: ORPHANED? | AM1: Risk Flags | AN1: Access Status | AO1: Review Status
A2: jsmith.azr@corp.onmicrosoft.com | B2: Jane Smith (Cloud Admin) | C2: 4c8e1f2a-9b3d-4e6f-a1c5-7d2e8f3a9b4c | D2: jsmith | E2: Yes | F2: 45173 | G2: 46246 | H2: Yes | I2: No | J2: microsoftAuthenticatorPush; sms | K2: Global Administrator | L2: Security Administrator | M2: 1 | N2: 1 | O2: Global Administrator | P2: 0 | Q2: Direct + Group | R2: SG-Azure-Platform-Owners | S2: 7e1d4b92-3a6c-4f8e-b1d5-2c9a8f4e6b3d | T2: 1 | U2: 1 | V2: Tenant-wide | W2: Yes | X2: jsmith@corp.com.au | Y2: Yes | Z2: Jane Smith | AA2: Cloud Platform Engineering | AB2: Principal Engineer | AC2: Permanent (BAU duty) | AD2: Tenant administration and break-glass escalation for the platform team. | AE2: CISO | AH2: 46152 | AI2: Convert to PIM eligible | AJ2: EXAMPLE ROW - delete before use. Standing Global Admin; also holds Azure Owner via group - coordinate with Azure RBAC Admins tab. | AK2: =IF($A2="","",IF($M2>0,"Yes","No")) | AL2: =IF($A2="","",IF(AND($E2="Yes",OR($Y2="No",$Y2="NOT FOUND")),"YES","")) | AM2: =IF($A2="","",TRIM(IF(AND($P2=0,$I2<>"Yes"),"T0-NoPhishResistant ","")&IF($H2="No","NoMFA ","")&IF(AND($P2=0,$M2>0),"T0-Standing ","")&IF(AND($P2=0,$Q2="Group only"),"T0-ViaGroupOnly ","")&IF($W2="Yes","AlsoAzureRBAC ",""))) | AN2: =IF($A2="","",IF(AG2="","Not Enrolled",IF(TODAY()>AG2,"Review Overdue",IF(AG2-TODAY()<=30,"Review Due Soon","Active")))) | AO2: =IF($A2="","",IF(AH2="","NOT REVIEWED",IF(TODAY()-AH2>90,"OVERDUE",IF(TODAY()-AH2>76,"Due Soon","Current"))))
AK3: =IF($A3="","",IF($M3>0,"Yes","No")) | AL3: =IF($A3="","",IF(AND($E3="Yes",OR($Y3="No",$Y3="NOT FOUND")),"YES","")) | AM3: =IF($A3="","",TRIM(IF(AND($P3=0,$I3<>"Yes"),"T0-NoPhishResistant ","")&IF($H3="No","NoMFA ","")&IF(AND($P3=0,$M3>0),"T0-Standing ","")&IF(AND($P3=0,$Q3="Group only"),"T0-ViaGroupOnly ","")&IF($W3="Yes","AlsoAzureRBAC ",""))) | AN3: =IF($A3="","",IF(AG3="","Not Enrolled",IF(TODAY()>AG3,"Review Overdue",IF(AG3-TODAY()<=30,"Review Due Soon","Active")))) | AO3: =IF($A3="","",IF(AH3="","NOT REVIEWED",IF(TODAY()-AH3>90,"OVERDUE",IF(TODAY()-AH3>76,"Due Soon","Current"))))
AK4: =IF($A4="","",IF($M4>0,"Yes","No")) | AL4: =IF($A4="","",IF(AND($E4="Yes",OR($Y4="No",$Y4="NOT FOUND")),"YES","")) | AM4: =IF($A4="","",TRIM(IF(AND($P4=0,$I4<>"Yes"),"T0-NoPhishResistant ","")&IF($H4="No","NoMFA ","")&IF(AND($P4=0,$M4>0),"T0-Standing ","")&IF(AND($P4=0,$Q4="Group only"),"T0-ViaGroupOnly ","")&IF($W4="Yes","AlsoAzureRBAC ",""))) | AN4: =IF($A4="","",IF(AG4="","Not Enrolled",IF(TODAY()>AG4,"Review Overdue",IF(AG4-TODAY()<=30,"Review Due Soon","Active")))) | AO4: =IF($A4="","",IF(AH4="","NOT REVIEWED",IF(TODAY()-AH4>90,"OVERDUE",IF(TODAY()-AH4>76,"Due Soon","Current"))))
AK5: =IF($A5="","",IF($M5>0,"Yes","No")) | AL5: =IF($A5="","",IF(AND($E5="Yes",OR($Y5="No",$Y5="NOT FOUND")),"YES","")) | AM5: =IF($A5="","",TRIM(IF(AND($P5=0,$I5<>"Yes"),"T0-NoPhishResistant ","")&IF($H5="No","NoMFA ","")&IF(AND($P5=0,$M5>0),"T0-Standing ","")&IF(AND($P5=0,$Q5="Group only"),"T0-ViaGroupOnly ","")&IF($W5="Yes","AlsoAzureRBAC ",""))) | AN5: =IF($A5="","",IF(AG5="","Not Enrolled",IF(TODAY()>AG5,"Review Overdue",IF(AG5-TODAY()<=30,"Review Due Soon","Active")))) | AO5: =IF($A5="","",IF(AH5="","NOT REVIEWED",IF(TODAY()-AH5>90,"OVERDUE",IF(TODAY()-AH5>76,"Due Soon","Current"))))
AK6: =IF($A6="","",IF($M6>0,"Yes","No")) | AL6: =IF($A6="","",IF(AND($E6="Yes",OR($Y6="No",$Y6="NOT FOUND")),"YES","")) | AM6: =IF($A6="","",TRIM(IF(AND($P6=0,$I6<>"Yes"),"T0-NoPhishResistant ","")&IF($H6="No","NoMFA ","")&IF(AND($P6=0,$M6>0),"T0-Standing ","")&IF(AND($P6=0,$Q6="Group only"),"T0-ViaGroupOnly ","")&IF($W6="Yes","AlsoAzureRBAC ",""))) | AN6: =IF($A6="","",IF(AG6="","Not Enrolled",IF(TODAY()>AG6,"Review Overdue",IF(AG6-TODAY()<=30,"Review Due Soon","Active")))) | AO6: =IF($A6="","",IF(AH6="","NOT REVIEWED",IF(TODAY()-AH6>90,"OVERDUE",IF(TODAY()-AH6>76,"Due Soon","Current"))))
AK7: =IF($A7="","",IF($M7>0,"Yes","No")) | AL7: =IF($A7="","",IF(AND($E7="Yes",OR($Y7="No",$Y7="NOT FOUND")),"YES","")) | AM7: =IF($A7="","",TRIM(IF(AND($P7=0,$I7<>"Yes"),"T0-NoPhishResistant ","")&IF($H7="No","NoMFA ","")&IF(AND($P7=0,$M7>0),"T0-Standing ","")&IF(AND($P7=0,$Q7="Group only"),"T0-ViaGroupOnly ","")&IF($W7="Yes","AlsoAzureRBAC ",""))) | AN7: =IF($A7="","",IF(AG7="","Not Enrolled",IF(TODAY()>AG7,"Review Overdue",IF(AG7-TODAY()<=30,"Review Due Soon","Active")))) | AO7: =IF($A7="","",IF(AH7="","NOT REVIEWED",IF(TODAY()-AH7>90,"OVERDUE",IF(TODAY()-AH7>76,"Due Soon","Current"))))
AK8: =IF($A8="","",IF($M8>0,"Yes","No")) | AL8: =IF($A8="","",IF(AND($E8="Yes",OR($Y8="No",$Y8="NOT FOUND")),"YES","")) | AM8: =IF($A8="","",TRIM(IF(AND($P8=0,$I8<>"Yes"),"T0-NoPhishResistant ","")&IF($H8="No","NoMFA ","")&IF(AND($P8=0,$M8>0),"T0-Standing ","")&IF(AND($P8=0,$Q8="Group only"),"T0-ViaGroupOnly ","")&IF($W8="Yes","AlsoAzureRBAC ",""))) | AN8: =IF($A8="","",IF(AG8="","Not Enrolled",IF(TODAY()>AG8,"Review Overdue",IF(AG8-TODAY()<=30,"Review Due Soon","Active")))) | AO8: =IF($A8="","",IF(AH8="","NOT REVIEWED",IF(TODAY()-AH8>90,"OVERDUE",IF(TODAY()-AH8>76,"Due Soon","Current"))))
AK9: =IF($A9="","",IF($M9>0,"Yes","No")) | AL9: =IF($A9="","",IF(AND($E9="Yes",OR($Y9="No",$Y9="NOT FOUND")),"YES","")) | AM9: =IF($A9="","",TRIM(IF(AND($P9=0,$I9<>"Yes"),"T0-NoPhishResistant ","")&IF($H9="No","NoMFA ","")&IF(AND($P9=0,$M9>0),"T0-Standing ","")&IF(AND($P9=0,$Q9="Group only"),"T0-ViaGroupOnly ","")&IF($W9="Yes","AlsoAzureRBAC ",""))) | AN9: =IF($A9="","",IF(AG9="","Not Enrolled",IF(TODAY()>AG9,"Review Overdue",IF(AG9-TODAY()<=30,"Review Due Soon","Active")))) | AO9: =IF($A9="","",IF(AH9="","NOT REVIEWED",IF(TODAY()-AH9>90,"OVERDUE",IF(TODAY()-AH9>76,"Due Soon","Current"))))
AK10: =IF($A10="","",IF($M10>0,"Yes","No")) | AL10: =IF($A10="","",IF(AND($E10="Yes",OR($Y10="No",$Y10="NOT FOUND")),"YES","")) | AM10: =IF($A10="","",TRIM(IF(AND($P10=0,$I10<>"Yes"),"T0-NoPhishResistant ","")&IF($H10="No","NoMFA ","")&IF(AND($P10=0,$M10>0),"T0-Standing ","")&IF(AND($P10=0,$Q10="Group only"),"T0-ViaGroupOnly ","")&IF($W10="Yes","AlsoAzureRBAC ",""))) | AN10: =IF($A10="","",IF(AG10="","Not Enrolled",IF(TODAY()>AG10,"Review Overdue",IF(AG10-TODAY()<=30,"Review Due Soon","Active")))) | AO10: =IF($A10="","",IF(AH10="","NOT REVIEWED",IF(TODAY()-AH10>90,"OVERDUE",IF(TODAY()-AH10>76,"Due Soon","Current"))))
AK11: =IF($A11="","",IF($M11>0,"Yes","No")) | AL11: =IF($A11="","",IF(AND($E11="Yes",OR($Y11="No",$Y11="NOT FOUND")),"YES","")) | AM11: =IF($A11="","",TRIM(IF(AND($P11=0,$I11<>"Yes"),"T0-NoPhishResistant ","")&IF($H11="No","NoMFA ","")&IF(AND($P11=0,$M11>0),"T0-Standing ","")&IF(AND($P11=0,$Q11="Group only"),"T0-ViaGroupOnly ","")&IF($W11="Yes","AlsoAzureRBAC ",""))) | AN11: =IF($A11="","",IF(AG11="","Not Enrolled",IF(TODAY()>AG11,"Review Overdue",IF(AG11-TODAY()<=30,"Review Due Soon","Active")))) | AO11: =IF($A11="","",IF(AH11="","NOT REVIEWED",IF(TODAY()-AH11>90,"OVERDUE",IF(TODAY()-AH11>76,"Due Soon","Current"))))
AK12: =IF($A12="","",IF($M12>0,"Yes","No")) | AL12: =IF($A12="","",IF(AND($E12="Yes",OR($Y12="No",$Y12="NOT FOUND")),"YES","")) | AM12: =IF($A12="","",TRIM(IF(AND($P12=0,$I12<>"Yes"),"T0-NoPhishResistant ","")&IF($H12="No","NoMFA ","")&IF(AND($P12=0,$M12>0),"T0-Standing ","")&IF(AND($P12=0,$Q12="Group only"),"T0-ViaGroupOnly ","")&IF($W12="Yes","AlsoAzureRBAC ",""))) | AN12: =IF($A12="","",IF(AG12="","Not Enrolled",IF(TODAY()>AG12,"Review Overdue",IF(AG12-TODAY()<=30,"Review Due Soon","Active")))) | AO12: =IF($A12="","",IF(AH12="","NOT REVIEWED",IF(TODAY()-AH12>90,"OVERDUE",IF(TODAY()-AH12>76,"Due Soon","Current"))))
AK13: =IF($A13="","",IF($M13>0,"Yes","No")) | AL13: =IF($A13="","",IF(AND($E13="Yes",OR($Y13="No",$Y13="NOT FOUND")),"YES","")) | AM13: =IF($A13="","",TRIM(IF(AND($P13=0,$I13<>"Yes"),"T0-NoPhishResistant ","")&IF($H13="No","NoMFA ","")&IF(AND($P13=0,$M13>0),"T0-Standing ","")&IF(AND($P13=0,$Q13="Group only"),"T0-ViaGroupOnly ","")&IF($W13="Yes","AlsoAzureRBAC ",""))) | AN13: =IF($A13="","",IF(AG13="","Not Enrolled",IF(TODAY()>AG13,"Review Overdue",IF(AG13-TODAY()<=30,"Review Due Soon","Active")))) | AO13: =IF($A13="","",IF(AH13="","NOT REVIEWED",IF(TODAY()-AH13>90,"OVERDUE",IF(TODAY()-AH13>76,"Due Soon","Current"))))
AK14: =IF($A14="","",IF($M14>0,"Yes","No")) | AL14: =IF($A14="","",IF(AND($E14="Yes",OR($Y14="No",$Y14="NOT FOUND")),"YES","")) | AM14: =IF($A14="","",TRIM(IF(AND($P14=0,$I14<>"Yes"),"T0-NoPhishResistant ","")&IF($H14="No","NoMFA ","")&IF(AND($P14=0,$M14>0),"T0-Standing ","")&IF(AND($P14=0,$Q14="Group only"),"T0-ViaGroupOnly ","")&IF($W14="Yes","AlsoAzureRBAC ",""))) | AN14: =IF($A14="","",IF(AG14="","Not Enrolled",IF(TODAY()>AG14,"Review Overdue",IF(AG14-TODAY()<=30,"Review Due Soon","Active")))) | AO14: =IF($A14="","",IF(AH14="","NOT REVIEWED",IF(TODAY()-AH14>90,"OVERDUE",IF(TODAY()-AH14>76,"Due Soon","Current"))))
... AK1001: =IF($A1001="","",IF($M1001>0,"Yes","No")) | AL1001: =IF($A1001="","",IF(AND($E1001="Yes",OR($Y1001="No",$Y1001="NOT FOUND")),"YES","")) | AM1001: =IF($A1001="","",TRIM(IF(AND($P1001=0,$I1001<>"Yes"),"T0-NoPhishResistant ","")&IF($H1001="No","NoMFA ","")&IF(AND($P1001=0,$M1001>0),"T0-Standing ","")&IF(AND($P1001=0,$Q1001="Group only"),"T0-ViaGroupOnly ","")&IF($W1001="Yes","AlsoAzureRBAC ",""))) | AN1001: =IF($A1001="","",IF(AG1001="","Not Enrolled",IF(TODAY()>AG1001,"Review Overdue",IF(AG1001-TODAY()<=30,"Review Due Soon","Active")))) | AO1001: =IF($A1001="","",IF(AH1001="","NOT REVIEWED",IF(TODAY()-AH1001>90,"OVERDUE",IF(TODAY()-AH1001>76,"Due Soon","Current"))))

Sheet Azure RBAC Admins
A1: Admin UPN | B1: Display Name | C1: Object ID | D1: Base Username | E1: Enabled | F1: Created | G1: Last Sign-In | H1: MFA Registered | I1: Phishing Resistant | J1: Auth Methods | K1: Azure RBAC Roles | L1: Highest Azure Role | M1: Azure Tier | N1: Sub or MG Scoped | O1: Assignment Route | P1: Granting Groups | Q1: Granting Group IDs | R1: Direct Assignments | S1: Group Assignments | T1: Also Holds Entra Role | U1: Standard Account UPN | V1: Standard Acct Enabled | W1: Person Display Name | X1: Department | Y1: Job Title | Z1: Access Type | AA1: Business Justification | AB1: Decided By | AC1: Review Decision Date | AD1: Next Review Due | AE1: Last Reviewed | AF1: Review Decision | AG1: Notes | AH1: ORPHANED? | AI1: Risk Flags | AJ1: Access Status | AK1: Review Status
A2: jsmith.azr@corp.onmicrosoft.com | B2: Jane Smith (Cloud Admin) | C2: 4c8e1f2a-9b3d-4e6f-a1c5-7d2e8f3a9b4c | D2: jsmith | E2: Yes | F2: 45173 | G2: 46246 | H2: Yes | I2: No | J2: microsoftAuthenticatorPush; sms | K2: Owner @ SUBSCRIPTION:prod-platform | L2: Owner | M2: 0 | N2: Yes | O2: Direct + Group | P2: SG-Azure-Platform-Owners | Q2: 7e1d4b92-3a6c-4f8e-b1d5-2c9a8f4e6b3d | R2: 1 | S2: 1 | T2: Yes | U2: jsmith@corp.com.au | V2: Yes | W2: Jane Smith | X2: Cloud Platform Engineering | Y2: Principal Engineer | Z2: Permanent (BAU duty) | AA2: Subscription ownership for platform infrastructure. | AB2: CISO | AE2: 46152 | AF2: Convert to PIM eligible | AG2: EXAMPLE ROW - delete before use. Standing Owner at subscription scope; also holds Entra Global Admin - coordinate with Entra Admins tab. | AH2: =IF($A2="","",IF(AND($E2="Yes",OR($V2="No",$V2="NOT FOUND")),"YES","")) | AI2: =IF($A2="","",TRIM(IF(AND($M2=0,$I2<>"Yes"),"T0-NoPhishResistant ","")&IF($H2="No","NoMFA ","")&IF(AND($M2=0,$O2="Group only"),"T0-ViaGroupOnly ","")&IF($N2="Yes","BroadAzureScope ","")&IF($T2="Yes","AlsoEntraRole ",""))) | AJ2: =IF($A2="","",IF(AD2="","Not Enrolled",IF(TODAY()>AD2,"Review Overdue",IF(AD2-TODAY()<=30,"Review Due Soon","Active")))) | AK2: =IF($A2="","",IF(AE2="","NOT REVIEWED",IF(TODAY()-AE2>90,"OVERDUE",IF(TODAY()-AE2>76,"Due Soon","Current"))))
AH3: =IF($A3="","",IF(AND($E3="Yes",OR($V3="No",$V3="NOT FOUND")),"YES","")) | AI3: =IF($A3="","",TRIM(IF(AND($M3=0,$I3<>"Yes"),"T0-NoPhishResistant ","")&IF($H3="No","NoMFA ","")&IF(AND($M3=0,$O3="Group only"),"T0-ViaGroupOnly ","")&IF($N3="Yes","BroadAzureScope ","")&IF($T3="Yes","AlsoEntraRole ",""))) | AJ3: =IF($A3="","",IF(AD3="","Not Enrolled",IF(TODAY()>AD3,"Review Overdue",IF(AD3-TODAY()<=30,"Review Due Soon","Active")))) | AK3: =IF($A3="","",IF(AE3="","NOT REVIEWED",IF(TODAY()-AE3>90,"OVERDUE",IF(TODAY()-AE3>76,"Due Soon","Current"))))
AH4: =IF($A4="","",IF(AND($E4="Yes",OR($V4="No",$V4="NOT FOUND")),"YES","")) | AI4: =IF($A4="","",TRIM(IF(AND($M4=0,$I4<>"Yes"),"T0-NoPhishResistant ","")&IF($H4="No","NoMFA ","")&IF(AND($M4=0,$O4="Group only"),"T0-ViaGroupOnly ","")&IF($N4="Yes","BroadAzureScope ","")&IF($T4="Yes","AlsoEntraRole ",""))) | AJ4: =IF($A4="","",IF(AD4="","Not Enrolled",IF(TODAY()>AD4,"Review Overdue",IF(AD4-TODAY()<=30,"Review Due Soon","Active")))) | AK4: =IF($A4="","",IF(AE4="","NOT REVIEWED",IF(TODAY()-AE4>90,"OVERDUE",IF(TODAY()-AE4>76,"Due Soon","Current"))))
AH5: =IF($A5="","",IF(AND($E5="Yes",OR($V5="No",$V5="NOT FOUND")),"YES","")) | AI5: =IF($A5="","",TRIM(IF(AND($M5=0,$I5<>"Yes"),"T0-NoPhishResistant ","")&IF($H5="No","NoMFA ","")&IF(AND($M5=0,$O5="Group only"),"T0-ViaGroupOnly ","")&IF($N5="Yes","BroadAzureScope ","")&IF($T5="Yes","AlsoEntraRole ",""))) | AJ5: =IF($A5="","",IF(AD5="","Not Enrolled",IF(TODAY()>AD5,"Review Overdue",IF(AD5-TODAY()<=30,"Review Due Soon","Active")))) | AK5: =IF($A5="","",IF(AE5="","NOT REVIEWED",IF(TODAY()-AE5>90,"OVERDUE",IF(TODAY()-AE5>76,"Due Soon","Current"))))
AH6: =IF($A6="","",IF(AND($E6="Yes",OR($V6="No",$V6="NOT FOUND")),"YES","")) | AI6: =IF($A6="","",TRIM(IF(AND($M6=0,$I6<>"Yes"),"T0-NoPhishResistant ","")&IF($H6="No","NoMFA ","")&IF(AND($M6=0,$O6="Group only"),"T0-ViaGroupOnly ","")&IF($N6="Yes","BroadAzureScope ","")&IF($T6="Yes","AlsoEntraRole ",""))) | AJ6: =IF($A6="","",IF(AD6="","Not Enrolled",IF(TODAY()>AD6,"Review Overdue",IF(AD6-TODAY()<=30,"Review Due Soon","Active")))) | AK6: =IF($A6="","",IF(AE6="","NOT REVIEWED",IF(TODAY()-AE6>90,"OVERDUE",IF(TODAY()-AE6>76,"Due Soon","Current"))))
AH7: =IF($A7="","",IF(AND($E7="Yes",OR($V7="No",$V7="NOT FOUND")),"YES","")) | AI7: =IF($A7="","",TRIM(IF(AND($M7=0,$I7<>"Yes"),"T0-NoPhishResistant ","")&IF($H7="No","NoMFA ","")&IF(AND($M7=0,$O7="Group only"),"T0-ViaGroupOnly ","")&IF($N7="Yes","BroadAzureScope ","")&IF($T7="Yes","AlsoEntraRole ",""))) | AJ7: =IF($A7="","",IF(AD7="","Not Enrolled",IF(TODAY()>AD7,"Review Overdue",IF(AD7-TODAY()<=30,"Review Due Soon","Active")))) | AK7: =IF($A7="","",IF(AE7="","NOT REVIEWED",IF(TODAY()-AE7>90,"OVERDUE",IF(TODAY()-AE7>76,"Due Soon","Current"))))
AH8: =IF($A8="","",IF(AND($E8="Yes",OR($V8="No",$V8="NOT FOUND")),"YES","")) | AI8: =IF($A8="","",TRIM(IF(AND($M8=0,$I8<>"Yes"),"T0-NoPhishResistant ","")&IF($H8="No","NoMFA ","")&IF(AND($M8=0,$O8="Group only"),"T0-ViaGroupOnly ","")&IF($N8="Yes","BroadAzureScope ","")&IF($T8="Yes","AlsoEntraRole ",""))) | AJ8: =IF($A8="","",IF(AD8="","Not Enrolled",IF(TODAY()>AD8,"Review Overdue",IF(AD8-TODAY()<=30,"Review Due Soon","Active")))) | AK8: =IF($A8="","",IF(AE8="","NOT REVIEWED",IF(TODAY()-AE8>90,"OVERDUE",IF(TODAY()-AE8>76,"Due Soon","Current"))))
AH9: =IF($A9="","",IF(AND($E9="Yes",OR($V9="No",$V9="NOT FOUND")),"YES","")) | AI9: =IF($A9="","",TRIM(IF(AND($M9=0,$I9<>"Yes"),"T0-NoPhishResistant ","")&IF($H9="No","NoMFA ","")&IF(AND($M9=0,$O9="Group only"),"T0-ViaGroupOnly ","")&IF($N9="Yes","BroadAzureScope ","")&IF($T9="Yes","AlsoEntraRole ",""))) | AJ9: =IF($A9="","",IF(AD9="","Not Enrolled",IF(TODAY()>AD9,"Review Overdue",IF(AD9-TODAY()<=30,"Review Due Soon","Active")))) | AK9: =IF($A9="","",IF(AE9="","NOT REVIEWED",IF(TODAY()-AE9>90,"OVERDUE",IF(TODAY()-AE9>76,"Due Soon","Current"))))
AH10: =IF($A10="","",IF(AND($E10="Yes",OR($V10="No",$V10="NOT FOUND")),"YES","")) | AI10: =IF($A10="","",TRIM(IF(AND($M10=0,$I10<>"Yes"),"T0-NoPhishResistant ","")&IF($H10="No","NoMFA ","")&IF(AND($M10=0,$O10="Group only"),"T0-ViaGroupOnly ","")&IF($N10="Yes","BroadAzureScope ","")&IF($T10="Yes","AlsoEntraRole ",""))) | AJ10: =IF($A10="","",IF(AD10="","Not Enrolled",IF(TODAY()>AD10,"Review Overdue",IF(AD10-TODAY()<=30,"Review Due Soon","Active")))) | AK10: =IF($A10="","",IF(AE10="","NOT REVIEWED",IF(TODAY()-AE10>90,"OVERDUE",IF(TODAY()-AE10>76,"Due Soon","Current"))))
AH11: =IF($A11="","",IF(AND($E11="Yes",OR($V11="No",$V11="NOT FOUND")),"YES","")) | AI11: =IF($A11="","",TRIM(IF(AND($M11=0,$I11<>"Yes"),"T0-NoPhishResistant ","")&IF($H11="No","NoMFA ","")&IF(AND($M11=0,$O11="Group only"),"T0-ViaGroupOnly ","")&IF($N11="Yes","BroadAzureScope ","")&IF($T11="Yes","AlsoEntraRole ",""))) | AJ11: =IF($A11="","",IF(AD11="","Not Enrolled",IF(TODAY()>AD11,"Review Overdue",IF(AD11-TODAY()<=30,"Review Due Soon","Active")))) | AK11: =IF($A11="","",IF(AE11="","NOT REVIEWED",IF(TODAY()-AE11>90,"OVERDUE",IF(TODAY()-AE11>76,"Due Soon","Current"))))
AH12: =IF($A12="","",IF(AND($E12="Yes",OR($V12="No",$V12="NOT FOUND")),"YES","")) | AI12: =IF($A12="","",TRIM(IF(AND($M12=0,$I12<>"Yes"),"T0-NoPhishResistant ","")&IF($H12="No","NoMFA ","")&IF(AND($M12=0,$O12="Group only"),"T0-ViaGroupOnly ","")&IF($N12="Yes","BroadAzureScope ","")&IF($T12="Yes","AlsoEntraRole ",""))) | AJ12: =IF($A12="","",IF(AD12="","Not Enrolled",IF(TODAY()>AD12,"Review Overdue",IF(AD12-TODAY()<=30,"Review Due Soon","Active")))) | AK12: =IF($A12="","",IF(AE12="","NOT REVIEWED",IF(TODAY()-AE12>90,"OVERDUE",IF(TODAY()-AE12>76,"Due Soon","Current"))))
AH13: =IF($A13="","",IF(AND($E13="Yes",OR($V13="No",$V13="NOT FOUND")),"YES","")) | AI13: =IF($A13="","",TRIM(IF(AND($M13=0,$I13<>"Yes"),"T0-NoPhishResistant ","")&IF($H13="No","NoMFA ","")&IF(AND($M13=0,$O13="Group only"),"T0-ViaGroupOnly ","")&IF($N13="Yes","BroadAzureScope ","")&IF($T13="Yes","AlsoEntraRole ",""))) | AJ13: =IF($A13="","",IF(AD13="","Not Enrolled",IF(TODAY()>AD13,"Review Overdue",IF(AD13-TODAY()<=30,"Review Due Soon","Active")))) | AK13: =IF($A13="","",IF(AE13="","NOT REVIEWED",IF(TODAY()-AE13>90,"OVERDUE",IF(TODAY()-AE13>76,"Due Soon","Current"))))
AH14: =IF($A14="","",IF(AND($E14="Yes",OR($V14="No",$V14="NOT FOUND")),"YES","")) | AI14: =IF($A14="","",TRIM(IF(AND($M14=0,$I14<>"Yes"),"T0-NoPhishResistant ","")&IF($H14="No","NoMFA ","")&IF(AND($M14=0,$O14="Group only"),"T0-ViaGroupOnly ","")&IF($N14="Yes","BroadAzureScope ","")&IF($T14="Yes","AlsoEntraRole ",""))) | AJ14: =IF($A14="","",IF(AD14="","Not Enrolled",IF(TODAY()>AD14,"Review Overdue",IF(AD14-TODAY()<=30,"Review Due Soon","Active")))) | AK14: =IF($A14="","",IF(AE14="","NOT REVIEWED",IF(TODAY()-AE14>90,"OVERDUE",IF(TODAY()-AE14>76,"Due Soon","Current"))))
... AH1001: =IF($A1001="","",IF(AND($E1001="Yes",OR($V1001="No",$V1001="NOT FOUND")),"YES","")) | AI1001: =IF($A1001="","",TRIM(IF(AND($M1001=0,$I1001<>"Yes"),"T0-NoPhishResistant ","")&IF($H1001="No","NoMFA ","")&IF(AND($M1001=0,$O1001="Group only"),"T0-ViaGroupOnly ","")&IF($N1001="Yes","BroadAzureScope ","")&IF($T1001="Yes","AlsoEntraRole ",""))) | AJ1001: =IF($A1001="","",IF(AD1001="","Not Enrolled",IF(TODAY()>AD1001,"Review Overdue",IF(AD1001-TODAY()<=30,"Review Due Soon","Active")))) | AK1001: =IF($A1001="","",IF(AE1001="","NOT REVIEWED",IF(TODAY()-AE1001>90,"OVERDUE",IF(TODAY()-AE1001>76,"Due Soon","Current"))))

Sheet On-Prem Admins
A1: SamAccountName | B1: Display Name | C1: Distinguished Name | D1: SID | E1: Base Username | F1: Enabled | G1: Created | H1: Last Logon | I1: Password Last Set | J1: Password Age (days) | K1: Password Never Expires | L1: Smartcard Required | M1: Privileged Groups | N1: Privileged Group Count | O1: Highest AD Group | P1: AD Tier | Q1: AdminCount | R1: Total Group Count | S1: Delegation | T1: Standard Account | U1: Standard Acct Enabled | V1: Person Display Name | W1: Department | X1: Job Title | Y1: ACL-Based Privilege | Z1: ACL Privilege Detail | AA1: Days Since Logon | AB1: ORPHANED? | AC1: Risk Flags | AD1: Access Type | AE1: Business Justification | AF1: Decided By | AG1: Review Decision Date | AH1: Next Review Due | AI1: Last Reviewed | AJ1: Review Decision | AK1: Notes | AL1: Access Status | AM1: Review Status
A2: jsmith-a | B2: Jane Smith (Admin) | C2: CN=jsmith-a,OU=Admin Accounts,DC=corp,DC=com,DC=au | D2: S-1-5-21-1004336348-1177238915-682003330-3312 | E2: jsmith | F2: Yes | G2: 44362 | H2: 46245 | I2: 45598 | J2: 650 | K2: No | L2: No | M2: Domain Admins; Server Operators | N2: 2 | O2: Domain Admins | P2: 0 | Q2: 1 | R2: 6 | S2: None | T2: jsmith | U2: Yes | V2: Jane Smith | W2: Cloud Platform Engineering | X2: Principal Engineer | Y2: No | AA2: =IF($H2="","",TODAY()-$H2) | AB2: =IF($A2="","",IF(AND($F2="Yes",OR($U2="No",$U2="NOT FOUND")),"YES","")) | AC2: =IF($A2="","",TRIM(IF(AND($P2=0,$L2<>"Yes"),"T0-NoSmartcard ","")&IF(AND($J2<>"",$J2>365),"StalePwd ","")&IF($K2="Yes","PwdNeverExpires ","")&IF(AND($S2<>"",$S2<>"None"),"Delegation ","")&IF(AND($Q2=1,$O2="None"),"StaleAdminCount ","")&IF(AND($F2="Yes",$H2=""),"NeverLoggedOn ",""))) | AD2: Permanent (BAU duty) | AE2: Domain controller maintenance and AD schema support. | AF2: Head of Infrastructure | AG2: 46042 | AI2: 46152 | AJ2: Retain - reduce scope | AK2: EXAMPLE ROW - delete before use. Domain Admin without smartcard; password 650 days old. | AL2: =IF($A2="","",IF(AH2="","Not Enrolled",IF(TODAY()>AH2,"Review Overdue",IF(AH2-TODAY()<=30,"Review Due Soon","Active")))) | AM2: =IF($A2="","",IF(AI2="","NOT REVIEWED",IF(TODAY()-AI2>90,"OVERDUE",IF(TODAY()-AI2>76,"Due Soon","Current"))))
AA3: =IF($H3="","",TODAY()-$H3) | AB3: =IF($A3="","",IF(AND($F3="Yes",OR($U3="No",$U3="NOT FOUND")),"YES","")) | AC3: =IF($A3="","",TRIM(IF(AND($P3=0,$L3<>"Yes"),"T0-NoSmartcard ","")&IF(AND($J3<>"",$J3>365),"StalePwd ","")&IF($K3="Yes","PwdNeverExpires ","")&IF(AND($S3<>"",$S3<>"None"),"Delegation ","")&IF(AND($Q3=1,$O3="None"),"StaleAdminCount ","")&IF(AND($F3="Yes",$H3=""),"NeverLoggedOn ",""))) | AL3: =IF($A3="","",IF(AH3="","Not Enrolled",IF(TODAY()>AH3,"Review Overdue",IF(AH3-TODAY()<=30,"Review Due Soon","Active")))) | AM3: =IF($A3="","",IF(AI3="","NOT REVIEWED",IF(TODAY()-AI3>90,"OVERDUE",IF(TODAY()-AI3>76,"Due Soon","Current"))))
AA4: =IF($H4="","",TODAY()-$H4) | AB4: =IF($A4="","",IF(AND($F4="Yes",OR($U4="No",$U4="NOT FOUND")),"YES","")) | AC4: =IF($A4="","",TRIM(IF(AND($P4=0,$L4<>"Yes"),"T0-NoSmartcard ","")&IF(AND($J4<>"",$J4>365),"StalePwd ","")&IF($K4="Yes","PwdNeverExpires ","")&IF(AND($S4<>"",$S4<>"None"),"Delegation ","")&IF(AND($Q4=1,$O4="None"),"StaleAdminCount ","")&IF(AND($F4="Yes",$H4=""),"NeverLoggedOn ",""))) | AL4: =IF($A4="","",IF(AH4="","Not Enrolled",IF(TODAY()>AH4,"Review Overdue",IF(AH4-TODAY()<=30,"Review Due Soon","Active")))) | AM4: =IF($A4="","",IF(AI4="","NOT REVIEWED",IF(TODAY()-AI4>90,"OVERDUE",IF(TODAY()-AI4>76,"Due Soon","Current"))))
AA5: =IF($H5="","",TODAY()-$H5) | AB5: =IF($A5="","",IF(AND($F5="Yes",OR($U5="No",$U5="NOT FOUND")),"YES","")) | AC5: =IF($A5="","",TRIM(IF(AND($P5=0,$L5<>"Yes"),"T0-NoSmartcard ","")&IF(AND($J5<>"",$J5>365),"StalePwd ","")&IF($K5="Yes","PwdNeverExpires ","")&IF(AND($S5<>"",$S5<>"None"),"Delegation ","")&IF(AND($Q5=1,$O5="None"),"StaleAdminCount ","")&IF(AND($F5="Yes",$H5=""),"NeverLoggedOn ",""))) | AL5: =IF($A5="","",IF(AH5="","Not Enrolled",IF(TODAY()>AH5,"Review Overdue",IF(AH5-TODAY()<=30,"Review Due Soon","Active")))) | AM5: =IF($A5="","",IF(AI5="","NOT REVIEWED",IF(TODAY()-AI5>90,"OVERDUE",IF(TODAY()-AI5>76,"Due Soon","Current"))))
AA6: =IF($H6="","",TODAY()-$H6) | AB6: =IF($A6="","",IF(AND($F6="Yes",OR($U6="No",$U6="NOT FOUND")),"YES","")) | AC6: =IF($A6="","",TRIM(IF(AND($P6=0,$L6<>"Yes"),"T0-NoSmartcard ","")&IF(AND($J6<>"",$J6>365),"StalePwd ","")&IF($K6="Yes","PwdNeverExpires ","")&IF(AND($S6<>"",$S6<>"None"),"Delegation ","")&IF(AND($Q6=1,$O6="None"),"StaleAdminCount ","")&IF(AND($F6="Yes",$H6=""),"NeverLoggedOn ",""))) | AL6: =IF($A6="","",IF(AH6="","Not Enrolled",IF(TODAY()>AH6,"Review Overdue",IF(AH6-TODAY()<=30,"Review Due Soon","Active")))) | AM6: =IF($A6="","",IF(AI6="","NOT REVIEWED",IF(TODAY()-AI6>90,"OVERDUE",IF(TODAY()-AI6>76,"Due Soon","Current"))))
AA7: =IF($H7="","",TODAY()-$H7) | AB7: =IF($A7="","",IF(AND($F7="Yes",OR($U7="No",$U7="NOT FOUND")),"YES","")) | AC7: =IF($A7="","",TRIM(IF(AND($P7=0,$L7<>"Yes"),"T0-NoSmartcard ","")&IF(AND($J7<>"",$J7>365),"StalePwd ","")&IF($K7="Yes","PwdNeverExpires ","")&IF(AND($S7<>"",$S7<>"None"),"Delegation ","")&IF(AND($Q7=1,$O7="None"),"StaleAdminCount ","")&IF(AND($F7="Yes",$H7=""),"NeverLoggedOn ",""))) | AL7: =IF($A7="","",IF(AH7="","Not Enrolled",IF(TODAY()>AH7,"Review Overdue",IF(AH7-TODAY()<=30,"Review Due Soon","Active")))) | AM7: =IF($A7="","",IF(AI7="","NOT REVIEWED",IF(TODAY()-AI7>90,"OVERDUE",IF(TODAY()-AI7>76,"Due Soon","Current"))))
AA8: =IF($H8="","",TODAY()-$H8) | AB8: =IF($A8="","",IF(AND($F8="Yes",OR($U8="No",$U8="NOT FOUND")),"YES","")) | AC8: =IF($A8="","",TRIM(IF(AND($P8=0,$L8<>"Yes"),"T0-NoSmartcard ","")&IF(AND($J8<>"",$J8>365),"StalePwd ","")&IF($K8="Yes","PwdNeverExpires ","")&IF(AND($S8<>"",$S8<>"None"),"Delegation ","")&IF(AND($Q8=1,$O8="None"),"StaleAdminCount ","")&IF(AND($F8="Yes",$H8=""),"NeverLoggedOn ",""))) | AL8: =IF($A8="","",IF(AH8="","Not Enrolled",IF(TODAY()>AH8,"Review Overdue",IF(AH8-TODAY()<=30,"Review Due Soon","Active")))) | AM8: =IF($A8="","",IF(AI8="","NOT REVIEWED",IF(TODAY()-AI8>90,"OVERDUE",IF(TODAY()-AI8>76,"Due Soon","Current"))))
AA9: =IF($H9="","",TODAY()-$H9) | AB9: =IF($A9="","",IF(AND($F9="Yes",OR($U9="No",$U9="NOT FOUND")),"YES","")) | AC9: =IF($A9="","",TRIM(IF(AND($P9=0,$L9<>"Yes"),"T0-NoSmartcard ","")&IF(AND($J9<>"",$J9>365),"StalePwd ","")&IF($K9="Yes","PwdNeverExpires ","")&IF(AND($S9<>"",$S9<>"None"),"Delegation ","")&IF(AND($Q9=1,$O9="None"),"StaleAdminCount ","")&IF(AND($F9="Yes",$H9=""),"NeverLoggedOn ",""))) | AL9: =IF($A9="","",IF(AH9="","Not Enrolled",IF(TODAY()>AH9,"Review Overdue",IF(AH9-TODAY()<=30,"Review Due Soon","Active")))) | AM9: =IF($A9="","",IF(AI9="","NOT REVIEWED",IF(TODAY()-AI9>90,"OVERDUE",IF(TODAY()-AI9>76,"Due Soon","Current"))))
AA10: =IF($H10="","",TODAY()-$H10) | AB10: =IF($A10="","",IF(AND($F10="Yes",OR($U10="No",$U10="NOT FOUND")),"YES","")) | AC10: =IF($A10="","",TRIM(IF(AND($P10=0,$L10<>"Yes"),"T0-NoSmartcard ","")&IF(AND($J10<>"",$J10>365),"StalePwd ","")&IF($K10="Yes","PwdNeverExpires ","")&IF(AND($S10<>"",$S10<>"None"),"Delegation ","")&IF(AND($Q10=1,$O10="None"),"StaleAdminCount ","")&IF(AND($F10="Yes",$H10=""),"NeverLoggedOn ",""))) | AL10: =IF($A10="","",IF(AH10="","Not Enrolled",IF(TODAY()>AH10,"Review Overdue",IF(AH10-TODAY()<=30,"Review Due Soon","Active")))) | AM10: =IF($A10="","",IF(AI10="","NOT REVIEWED",IF(TODAY()-AI10>90,"OVERDUE",IF(TODAY()-AI10>76,"Due Soon","Current"))))
AA11: =IF($H11="","",TODAY()-$H11) | AB11: =IF($A11="","",IF(AND($F11="Yes",OR($U11="No",$U11="NOT FOUND")),"YES","")) | AC11: =IF($A11="","",TRIM(IF(AND($P11=0,$L11<>"Yes"),"T0-NoSmartcard ","")&IF(AND($J11<>"",$J11>365),"StalePwd ","")&IF($K11="Yes","PwdNeverExpires ","")&IF(AND($S11<>"",$S11<>"None"),"Delegation ","")&IF(AND($Q11=1,$O11="None"),"StaleAdminCount ","")&IF(AND($F11="Yes",$H11=""),"NeverLoggedOn ",""))) | AL11: =IF($A11="","",IF(AH11="","Not Enrolled",IF(TODAY()>AH11,"Review Overdue",IF(AH11-TODAY()<=30,"Review Due Soon","Active")))) | AM11: =IF($A11="","",IF(AI11="","NOT REVIEWED",IF(TODAY()-AI11>90,"OVERDUE",IF(TODAY()-AI11>76,"Due Soon","Current"))))
AA12: =IF($H12="","",TODAY()-$H12) | AB12: =IF($A12="","",IF(AND($F12="Yes",OR($U12="No",$U12="NOT FOUND")),"YES","")) | AC12: =IF($A12="","",TRIM(IF(AND($P12=0,$L12<>"Yes"),"T0-NoSmartcard ","")&IF(AND($J12<>"",$J12>365),"StalePwd ","")&IF($K12="Yes","PwdNeverExpires ","")&IF(AND($S12<>"",$S12<>"None"),"Delegation ","")&IF(AND($Q12=1,$O12="None"),"StaleAdminCount ","")&IF(AND($F12="Yes",$H12=""),"NeverLoggedOn ",""))) | AL12: =IF($A12="","",IF(AH12="","Not Enrolled",IF(TODAY()>AH12,"Review Overdue",IF(AH12-TODAY()<=30,"Review Due Soon","Active")))) | AM12: =IF($A12="","",IF(AI12="","NOT REVIEWED",IF(TODAY()-AI12>90,"OVERDUE",IF(TODAY()-AI12>76,"Due Soon","Current"))))
AA13: =IF($H13="","",TODAY()-$H13) | AB13: =IF($A13="","",IF(AND($F13="Yes",OR($U13="No",$U13="NOT FOUND")),"YES","")) | AC13: =IF($A13="","",TRIM(IF(AND($P13=0,$L13<>"Yes"),"T0-NoSmartcard ","")&IF(AND($J13<>"",$J13>365),"StalePwd ","")&IF($K13="Yes","PwdNeverExpires ","")&IF(AND($S13<>"",$S13<>"None"),"Delegation ","")&IF(AND($Q13=1,$O13="None"),"StaleAdminCount ","")&IF(AND($F13="Yes",$H13=""),"NeverLoggedOn ",""))) | AL13: =IF($A13="","",IF(AH13="","Not Enrolled",IF(TODAY()>AH13,"Review Overdue",IF(AH13-TODAY()<=30,"Review Due Soon","Active")))) | AM13: =IF($A13="","",IF(AI13="","NOT REVIEWED",IF(TODAY()-AI13>90,"OVERDUE",IF(TODAY()-AI13>76,"Due Soon","Current"))))
AA14: =IF($H14="","",TODAY()-$H14) | AB14: =IF($A14="","",IF(AND($F14="Yes",OR($U14="No",$U14="NOT FOUND")),"YES","")) | AC14: =IF($A14="","",TRIM(IF(AND($P14=0,$L14<>"Yes"),"T0-NoSmartcard ","")&IF(AND($J14<>"",$J14>365),"StalePwd ","")&IF($K14="Yes","PwdNeverExpires ","")&IF(AND($S14<>"",$S14<>"None"),"Delegation ","")&IF(AND($Q14=1,$O14="None"),"StaleAdminCount ","")&IF(AND($F14="Yes",$H14=""),"NeverLoggedOn ",""))) | AL14: =IF($A14="","",IF(AH14="","Not Enrolled",IF(TODAY()>AH14,"Review Overdue",IF(AH14-TODAY()<=30,"Review Due Soon","Active")))) | AM14: =IF($A14="","",IF(AI14="","NOT REVIEWED",IF(TODAY()-AI14>90,"OVERDUE",IF(TODAY()-AI14>76,"Due Soon","Current"))))
... AA1001: =IF($H1001="","",TODAY()-$H1001) | AB1001: =IF($A1001="","",IF(AND($F1001="Yes",OR($U1001="No",$U1001="NOT FOUND")),"YES","")) | AC1001: =IF($A1001="","",TRIM(IF(AND($P1001=0,$L1001<>"Yes"),"T0-NoSmartcard ","")&IF(AND($J1001<>"",$J1001>365),"StalePwd ","")&IF($K1001="Yes","PwdNeverExpires ","")&IF(AND($S1001<>"",$S1001<>"None"),"Delegation ","")&IF(AND($Q1001=1,$O1001="None"),"StaleAdminCount ","")&IF(AND($F1001="Yes",$H1001=""),"NeverLoggedOn ",""))) | AL1001: =IF($A1001="","",IF(AH1001="","Not Enrolled",IF(TODAY()>AH1001,"Review Overdue",IF(AH1001-TODAY()<=30,"Review Due Soon","Active")))) | AM1001: =IF($A1001="","",IF(AI1001="","NOT REVIEWED",IF(TODAY()-AI1001>90,"OVERDUE",IF(TODAY()-AI1001>76,"Due Soon","Current"))))

Sheet Role Tiers
A1: Role tiering model
A2: Reference only. Tiers are assigned by the collection scripts - to change the model, edit the $RoleTiers / $GroupTiers table at the top of each script and re-run.
A4: Tier | B4: Role / Group | C4: Plane | D4: Why this tier
A5: 0 | B5: Global Administrator | C5: Entra | D5: Unrestricted control of the tenant.
A6: 0 | B6: Privileged Role Administrator | C6: Entra | D6: Can grant any directory role, including Global Administrator.
A7: 0 | B7: Privileged Authentication Administrator | C7: Entra | D7: Can reset credentials for any user, including Global Administrators.
A8: 0 | B8: Application Administrator | C8: Entra | D8: Can add credentials to any service principal, including highly privileged ones. A well-known escalation path to full tenant control.
A9: 0 | B9: Cloud Application Administrator | C9: Entra | D9: As above, excluding on-premises application proxy.
A10: 0 | B10: Hybrid Identity Administrator | C10: Entra | D10: Controls the sync configuration bridging AD and Entra - compromise reaches both planes.
A11: 0 | B11: Owner | C11: Azure RBAC | D11: Full control of the scope including the ability to grant access to others.
A12: 0 | B12: User Access Administrator | C12: Azure RBAC | D12: Can grant itself and anyone else any role at the scope.
A13: 0 | B13: Role Based Access Control Administrator | C13: Azure RBAC | D13: Can manage role assignments at the scope.
A14: 0 | B14: Domain Admins | C14: AD | D14: Full control of the domain.
A15: 0 | B15: Enterprise Admins | C15: AD | D15: Full control of the forest.
A16: 0 | B16: Schema Admins | C16: AD | D16: Can modify the schema - permanent, forest-wide, effectively irreversible.
... A32: 2 | B32: Reader and equivalent read-only roles | C32: All | D32: Visibility without change. Still worth inventorying - reconnaissance value.

Sheet Reference
A1: Yes / No | B1: Review Decision | C1: Access Type | D1: Decided By | E1: Access Status (computed - reference only) | F1: Review Status (computed - reference only) | G1: Auto-Removal Risk (computed - reference only)
A2: Yes | B2: Self-Approved | C2: Permanent (BAU duty) | D2: Self | E2: Active | F2: Current | G2: Not At Risk
A3: No | B3: Self-Removed | C3: Project - time limited | D3: Auto (No Response) | E3: Review Due Soon | F3: Due Soon | G3: At Risk
A4: Unknown | B4: Auto-Removed (No Response) | C4: On-call / rotational | D4: Escalation Reviewer (Tier 0) | E4: Review Overdue | F4: OVERDUE
A5: N/A | B5: Escalated - Approved | C5: Break-glass | D5: Security Team (Override) | E5: Not Enrolled | F5: NOT REVIEWED
B6: Escalated - Denied | C6: Vendor / third party | D6: NOT YET REVIEWED
B7: Pending Review | C7: Unknown | D7: N/A
B8: Manual Override
