Workbook

Sheet Dashboard
B2: Service Identity Inventory - Dashboard
B3: Recalculates from the identity and map tabs. Press F9 if calculation is set to manual.
B5: POPULATION | C5: Accounts | D5: Service Principals | E5: Managed Identities | F5: Why it matters
B6: Total identities recorded | C6: =COUNTA(Accounts!$C$2:$C$201) -> 1 | D6: =COUNTA('Service Principals'!$C$2:$C$201) -> 1 | E6: =COUNTA('Managed Identities'!$C$2:$C$201) -> 1 | F6: Rows with an Object ID.
B7: Production | C7: =COUNTIF(Accounts!$AK$2:$AK$201,"Production") -> 1 | D7: =COUNTIF('Service Principals'!$AN$2:$AN$201,"Production") -> 1 | E7: =COUNTIF('Managed Identities'!$AI$2:$AI$201,"Production") -> 1 | F7: Production blast radius.
B8: Critical criticality | C8: =COUNTIF(Accounts!$AL$2:$AL$201,"Critical") -> 1 | D8: =COUNTIF('Service Principals'!$AO$2:$AO$201,"Critical") -> 0 | E8: =COUNTIF('Managed Identities'!$AJ$2:$AJ$201,"Critical") -> 0 | F8: Prioritise for review and hardening.
B10: CONDITIONAL ACCESS EXCLUSIONS | C10: Accounts | D10: Service Principals | E10: Managed Identities | F10: Why it matters
B11: Excluded from one or more CA policies | C11: =COUNTIF(Accounts!$V$2:$V$201,"Yes") -> 1 | D11: =COUNTIF('Service Principals'!$Y$2:$Y$201,"Yes") -> 0 | E11: =COUNTIF('Managed Identities'!$T$2:$T$201,"Yes") -> 1 | F11: The core risk metric.
B12: ... EXPIRED | C12: =COUNTIF(Accounts!$AD$2:$AD$201,"EXPIRED") -> 0 | D12: =COUNTIF('Service Principals'!$AG$2:$AG$201,"EXPIRED") -> 0 | E12: =COUNTIF('Managed Identities'!$AB$2:$AB$201,"EXPIRED") -> 0 | F12: Past the approved end date. Remove today.
B13: ... NO EXPIRY SET | C13: =COUNTIF(Accounts!$AD$2:$AD$201,"NO EXPIRY SET") -> 0 | D13: =COUNTIF('Service Principals'!$AG$2:$AG$201,"NO EXPIRY SET") -> 0 | E13: =COUNTIF('Managed Identities'!$AB$2:$AB$201,"NO EXPIRY SET") -> 0 | F13: Permanent exclusions with no review date - the usual audit finding.
B14: ... expiring within 30 days | C14: =COUNTIF(Accounts!$AD$2:$AD$201,"Expiring Soon") -> 0 | D14: =COUNTIF('Service Principals'!$AG$2:$AG$201,"Expiring Soon") -> 0 | E14: =COUNTIF('Managed Identities'!$AB$2:$AB$201,"Expiring Soon") -> 0 | F14: Renew with fresh approval or plan removal.
B15: ... no recorded approver | C15: =COUNTIFS(Accounts!$V$2:$V$201,"Yes",Accounts!$AA$2:$AA$201,"") -> 0 | D15: =COUNTIFS('Service Principals'!$Y$2:$Y$201,"Yes",'Service Principals'!$AD$2:$AD$201,"") -> 0 | E15: =COUNTIFS('Managed Identities'!$T$2:$T$201,"Yes",'Managed Identities'!$Y$2:$Y$201,"") -> 0 | F15: No accountability trail.
B16: ... no compensating control | C16: =COUNTIFS(Accounts!$V$2:$V$201,"Yes",Accounts!$AE$2:$AE$201,"") -> 0 | D16: =COUNTIFS('Service Principals'!$Y$2:$Y$201,"Yes",'Service Principals'!$AH$2:$AH$201,"") -> 0 | E16: =COUNTIFS('Managed Identities'!$T$2:$T$201,"Yes",'Managed Identities'!$AC$2:$AC$201,"") -> 0 | F16: Excluded and unmitigated.
B17: ... excluded directly, not via a group | C17: =COUNTIF(Accounts!$W$2:$W$201,"*Direct*") -> 0 | D17: =COUNTIF('Service Principals'!$Z$2:$Z$201,"*Direct*") -> 0 | E17: =COUNTIF('Managed Identities'!$U$2:$U$201,"*Direct*") -> 0 | F17: Bypasses group-based governance entirely.
B19: AZURE PRIVILEGE | C19: Accounts | D19: Service Principals | E19: Managed Identities | F19: Why it matters
B20: Holds any Azure RBAC role | C20: =COUNTIF(Accounts!$T$2:$T$201,"<>")-COUNTIF(Accounts!$T$2:$T$201,"") -> 0 | D20: =COUNTIF('Service Principals'!$W$2:$W$201,"<>")-COUNTIF('Service Principals'!$W$2:$W$201,"") -> 1 | E20: =COUNTIF('Managed Identities'!$Q$2:$Q$201,"<>")-COUNTIF('Managed Identities'!$Q$2:$Q$201,"") -> 1 | F20: Entra identity plus Azure control-plane rights.
B21: Owner or User Access Administrator | C21: =COUNTIF(Accounts!$T$2:$T$201,"Owner")+COUNTIF(Accounts!$T$2:$T$201,"User Access Administrator") -> 0 | D21: =COUNTIF('Service Principals'!$W$2:$W$201,"Owner")+COUNTIF('Service Principals'!$W$2:$W$201,"User Access Administrator") -> 0 | E21: =COUNTIF('Managed Identities'!$Q$2:$Q$201,"Owner")+COUNTIF('Managed Identities'!$Q$2:$Q$201,"User Access Administrator") -> 0 | F21: Can grant itself anything. The shortest list you should have.
B22: Subscription or management group scoped | C22: =COUNTIF(Accounts!$U$2:$U$201,"Yes") -> 0 | D22: =COUNTIF('Service Principals'!$X$2:$X$201,"Yes") -> 0 | E22: =COUNTIF('Managed Identities'!$R$2:$R$201,"Yes") -> 0 | F22: Broad scope multiplies the impact of any credential compromise.
B23: CA-excluded AND Azure privileged | C23: =COUNTIFS(Accounts!$V$2:$V$201,"Yes",Accounts!$U$2:$U$201,"Yes") -> 0 | D23: =COUNTIFS('Service Principals'!$Y$2:$Y$201,"Yes",'Service Principals'!$X$2:$X$201,"Yes") -> 0 | E23: =COUNTIFS('Managed Identities'!$T$2:$T$201,"Yes",'Managed Identities'!$R$2:$R$201,"Yes") -> 0 | F23: No conditional access, broad Azure rights. Work this list first.
B25: OWNERSHIP | C25: Accounts | D25: Service Principals | E25: Managed Identities | F25: Why it matters
B26: No owning team | C26: =COUNTIFS(Accounts!$C$2:$C$201,"<>",Accounts!$AF$2:$AF$201,"")+COUNTIF(Accounts!$AF$2:$AF$201,"UNASSIGNED - NEEDS OWNER") -> 0 | D26: =COUNTIFS('Service Principals'!$C$2:$C$201,"<>",'Service Principals'!$AI$2:$AI$201,"")+COUNTIF('Service Principals'!$AI$2:$AI$201,"UNASSIGNED - NEEDS OWNER") -> 0 | E26: =COUNTIFS('Managed Identities'!$C$2:$C$201,"<>",'Managed Identities'!$AD$2:$AD$201,"")+COUNTIF('Managed Identities'!$AD$2:$AD$201,"UNASSIGNED - NEEDS OWNER") -> 0 | F26: Orphans cannot be attested or safely decommissioned.
B27: No confirmed individual owner | C27: =COUNTIFS(Accounts!$C$2:$C$201,"<>",Accounts!$AG$2:$AG$201,"") -> 0 | D27: =COUNTIFS('Service Principals'!$C$2:$C$201,"<>",'Service Principals'!$AJ$2:$AJ$201,"") -> 0 | E27: =COUNTIFS('Managed Identities'!$C$2:$C$201,"<>",'Managed Identities'!$AE$2:$AE$201,"") -> 0 | F27: A team alone is not accountable.
B28: No backup owner | C28: =COUNTIFS(Accounts!$C$2:$C$201,"<>",Accounts!$AI$2:$AI$201,"") -> 0 | D28: =COUNTIFS('Service Principals'!$C$2:$C$201,"<>",'Service Principals'!$AL$2:$AL$201,"") -> 0 | E28: =COUNTIFS('Managed Identities'!$C$2:$C$201,"<>",'Managed Identities'!$AG$2:$AG$201,"") -> 0 | F28: Single point of knowledge failure.
B30: HYGIENE | C30: Accounts | D30: Service Principals | E30: Managed Identities | F30: Why it matters
B31: No sign-in in 90+ days | C31: =COUNTIF(Accounts!$Q$2:$Q$201,">90") -> 0 | D31: =COUNTIF('Service Principals'!$R$2:$R$201,">90") -> 0 | E31: =COUNTIF('Managed Identities'!$I$2:$I$201,">90") -> 0 | F31: Decommission candidates.
B32: Review OVERDUE or never reviewed | C32: =COUNTIF(Accounts!$AQ$2:$AQ$201,"OVERDUE")+COUNTIF(Accounts!$AQ$2:$AQ$201,"NOT REVIEWED") -> 0 | D32: =COUNTIF('Service Principals'!$AT$2:$AT$201,"OVERDUE")+COUNTIF('Service Principals'!$AT$2:$AT$201,"NOT REVIEWED") -> 0 | E32: =COUNTIF('Managed Identities'!$AO$2:$AO$201,"OVERDUE")+COUNTIF('Managed Identities'!$AO$2:$AO$201,"NOT REVIEWED") -> 0 | F32: 90-day attestation cycle.
B33: Disabled but still present | C33: =COUNTIF(Accounts!$G$2:$G$201,"No") -> 0 | D33: =COUNTIF('Service Principals'!$F$2:$F$201,"No") -> 0 | E33: n/a | F33: Disabled accounts retain group memberships and permissions.
B35: SERVICE PRINCIPAL CREDENTIALS | C35: Value | F35: Why it matters
B36: Credentials expiring within 30 days | C36: =COUNTIFS('Service Principals'!$S$2:$S$201,"<=30",'Service Principals'!$S$2:$S$201,">=0") -> 0 | F36: Outage risk. Rotate now.
B37: Credentials already expired | C37: =COUNTIF('Service Principals'!$S$2:$S$201,"<0") -> 0 | F37: Broken, or there is a second credential you have not inventoried.
B38: Using client secrets | C38: =COUNTIF('Service Principals'!$I$2:$I$201,"*Secret*") -> 0 | F38: Weakest option. Prefer certificates or workload identity federation.
B39: More than two credentials | C39: =COUNTIF('Service Principals'!$K$2:$K$201,">2") -> 0 | F39: Usually an orphaned secret nobody dared delete.
B40: High-risk Graph permission | C40: =COUNTIF('Service Principals'!$M$2:$M$201,"High") -> 1 | F40: Directory write, role management, mail send and similar.
B41: No registered owner in Graph | C41: =COUNTIFS('Service Principals'!$C$2:$C$201,"<>",'Service Principals'!$P$2:$P$201,"") -> 0 | F41: Nothing in the directory says who is responsible.
B42: Multi-tenant AND CA-excluded | C42: =COUNTIFS('Service Principals'!$E$2:$E$201,"Multi-tenant",'Service Principals'!$Y$2:$Y$201,"Yes") -> 0 | F42: CA cannot target these - compensating controls are mandatory.
B43: Managed identities that could use federation | C43: =COUNTIF('Managed Identities'!$S$2:$S$201,"Yes") -> 0 | F43: Migration backlog away from long-lived credentials.
B45: RISK CONCENTRATION | C45: Value | F45: Why it matters
B46: Privileged accounts with NO MFA registered | C46: =COUNTIFS(Accounts!$L$2:$L$201,"<>None",Accounts!$L$2:$L$201,"<>",Accounts!$K$2:$K$201,"Not Registered") -> 0 | F46: The highest-severity number in this workbook. Standing admin rights with no strong authentication.
B47: Standing privileged accounts (permanent roles) | C47: =COUNTIFS(Accounts!$L$2:$L$201,"<>None",Accounts!$L$2:$L$201,"<>") -> 0 | F47: Permanently assigned directory roles.
B48: PIM-eligible only (activated on demand) | C48: =COUNTIFS(Accounts!$L$2:$L$201,"None",Accounts!$M$2:$M$201,"<>None",Accounts!$M$2:$M$201,"<>") -> 0 | F48: The ratio of these two rows is your privilege maturity. Higher eligible-only is better.
...

Sheet Charts
A1: Charts
A2: Helper tables feed the charts. Only the exclusion group names need entering by hand.
A4: 1. Exclusion concentration
A5: Enter your exclusion group names in the yellow cells. Counts update automatically. Exclusions cluster hard - this usually turns 'review 40 exclusions' into 'review 3 groups'.
A6: Exclusion group name (enter these) | B6: Identities
A7: CA-Excl-ServiceAccounts | B7: =IF($A7="","",COUNTIF(Accounts!$X$2:$X$201,"*"&$A7&"*")+COUNTIF('Service Principals'!$AA$2:$AA$201,"*"&$A7&"*")+COUNTIF('Managed Identities'!$V$2:$V$201,"*"&$A7&"*")) -> 1
A8: CA-Excl-WorkloadIdentities | B8: =IF($A8="","",COUNTIF(Accounts!$X$2:$X$201,"*"&$A8&"*")+COUNTIF('Service Principals'!$AA$2:$AA$201,"*"&$A8&"*")+COUNTIF('Managed Identities'!$V$2:$V$201,"*"&$A8&"*")) -> 1
B9: =IF($A9="","",COUNTIF(Accounts!$X$2:$X$201,"*"&$A9&"*")+COUNTIF('Service Principals'!$AA$2:$AA$201,"*"&$A9&"*")+COUNTIF('Managed Identities'!$V$2:$V$201,"*"&$A9&"*"))
B10: =IF($A10="","",COUNTIF(Accounts!$X$2:$X$201,"*"&$A10&"*")+COUNTIF('Service Principals'!$AA$2:$AA$201,"*"&$A10&"*")+COUNTIF('Managed Identities'!$V$2:$V$201,"*"&$A10&"*"))
B11: =IF($A11="","",COUNTIF(Accounts!$X$2:$X$201,"*"&$A11&"*")+COUNTIF('Service Principals'!$AA$2:$AA$201,"*"&$A11&"*")+COUNTIF('Managed Identities'!$V$2:$V$201,"*"&$A11&"*"))
B12: =IF($A12="","",COUNTIF(Accounts!$X$2:$X$201,"*"&$A12&"*")+COUNTIF('Service Principals'!$AA$2:$AA$201,"*"&$A12&"*")+COUNTIF('Managed Identities'!$V$2:$V$201,"*"&$A12&"*"))
B13: =IF($A13="","",COUNTIF(Accounts!$X$2:$X$201,"*"&$A13&"*")+COUNTIF('Service Principals'!$AA$2:$AA$201,"*"&$A13&"*")+COUNTIF('Managed Identities'!$V$2:$V$201,"*"&$A13&"*"))
B14: =IF($A14="","",COUNTIF(Accounts!$X$2:$X$201,"*"&$A14&"*")+COUNTIF('Service Principals'!$AA$2:$AA$201,"*"&$A14&"*")+COUNTIF('Managed Identities'!$V$2:$V$201,"*"&$A14&"*"))
B15: =IF($A15="","",COUNTIF(Accounts!$X$2:$X$201,"*"&$A15&"*")+COUNTIF('Service Principals'!$AA$2:$AA$201,"*"&$A15&"*")+COUNTIF('Managed Identities'!$V$2:$V$201,"*"&$A15&"*"))
B16: =IF($A16="","",COUNTIF(Accounts!$X$2:$X$201,"*"&$A16&"*")+COUNTIF('Service Principals'!$AA$2:$AA$201,"*"&$A16&"*")+COUNTIF('Managed Identities'!$V$2:$V$201,"*"&$A16&"*"))
B17: =IF($A17="","",COUNTIF(Accounts!$X$2:$X$201,"*"&$A17&"*")+COUNTIF('Service Principals'!$AA$2:$AA$201,"*"&$A17&"*")+COUNTIF('Managed Identities'!$V$2:$V$201,"*"&$A17&"*"))
B18: =IF($A18="","",COUNTIF(Accounts!$X$2:$X$201,"*"&$A18&"*")+COUNTIF('Service Principals'!$AA$2:$AA$201,"*"&$A18&"*")+COUNTIF('Managed Identities'!$V$2:$V$201,"*"&$A18&"*"))
B19: =IF($A19="","",COUNTIF(Accounts!$X$2:$X$201,"*"&$A19&"*")+COUNTIF('Service Principals'!$AA$2:$AA$201,"*"&$A19&"*")+COUNTIF('Managed Identities'!$V$2:$V$201,"*"&$A19&"*"))
B20: =IF($A20="","",COUNTIF(Accounts!$X$2:$X$201,"*"&$A20&"*")+COUNTIF('Service Principals'!$AA$2:$AA$201,"*"&$A20&"*")+COUNTIF('Managed Identities'!$V$2:$V$201,"*"&$A20&"*"))
B21: =IF($A21="","",COUNTIF(Accounts!$X$2:$X$201,"*"&$A21&"*")+COUNTIF('Service Principals'!$AA$2:$AA$201,"*"&$A21&"*")+COUNTIF('Managed Identities'!$V$2:$V$201,"*"&$A21&"*"))
A24: 2. Account category by exclusion status
A25: Hunt the anomaly: exclusions in the Standard User bar are either miscategorised service accounts or real people quietly exempted from MFA.
A26: Account category | B26: Excluded | C26: Not excluded
A27: Standard User | B27: =COUNTIFS(Accounts!$D$2:$D$201,"*"&$A27&"*",Accounts!$V$2:$V$201,"Yes") -> 0 | C27: =COUNTIFS(Accounts!$D$2:$D$201,"*"&$A27&"*",Accounts!$V$2:$V$201,"No") -> 0
A28: Service Account | B28: =COUNTIFS(Accounts!$D$2:$D$201,"*"&$A28&"*",Accounts!$V$2:$V$201,"Yes") -> 1 | C28: =COUNTIFS(Accounts!$D$2:$D$201,"*"&$A28&"*",Accounts!$V$2:$V$201,"No") -> 0
A29: Privileged / Admin | B29: =COUNTIFS(Accounts!$D$2:$D$201,"*"&$A29&"*",Accounts!$V$2:$V$201,"Yes") -> 0 | C29: =COUNTIFS(Accounts!$D$2:$D$201,"*"&$A29&"*",Accounts!$V$2:$V$201,"No") -> 0
A30: Break-Glass | B30: =COUNTIFS(Accounts!$D$2:$D$201,"*"&$A30&"*",Accounts!$V$2:$V$201,"Yes") -> 0 | C30: =COUNTIFS(Accounts!$D$2:$D$201,"*"&$A30&"*",Accounts!$V$2:$V$201,"No") -> 0
A31: Guest | B31: =COUNTIFS(Accounts!$D$2:$D$201,"*"&$A31&"*",Accounts!$V$2:$V$201,"Yes") -> 0 | C31: =COUNTIFS(Accounts!$D$2:$D$201,"*"&$A31&"*",Accounts!$V$2:$V$201,"No") -> 0
A32: Shared | B32: =COUNTIFS(Accounts!$D$2:$D$201,"*"&$A32&"*",Accounts!$V$2:$V$201,"Yes") -> 0 | C32: =COUNTIFS(Accounts!$D$2:$D$201,"*"&$A32&"*",Accounts!$V$2:$V$201,"No") -> 0
A33: Test Account | B33: =COUNTIFS(Accounts!$D$2:$D$201,"*"&$A33&"*",Accounts!$V$2:$V$201,"Yes") -> 0 | C33: =COUNTIFS(Accounts!$D$2:$D$201,"*"&$A33&"*",Accounts!$V$2:$V$201,"No") -> 0
A36: 3. Service principal credential expiry timeline
A37: Sizes the rotation workload and shows when it lands. A tall bar in the first two buckets is an outage risk, not a planning problem.
A38: Window | B38: Credentials
A39: Already expired | B39: =COUNTIF('Service Principals'!$S$2:$S$201,"<0") -> 0
A40: 0-30 days | B40: =COUNTIFS('Service Principals'!$S$2:$S$201,">=0",'Service Principals'!$S$2:$S$201,"<=30") -> 0
A41: 31-60 days | B41: =COUNTIFS('Service Principals'!$S$2:$S$201,">30",'Service Principals'!$S$2:$S$201,"<=60") -> 1
A42: 61-90 days | B42: =COUNTIFS('Service Principals'!$S$2:$S$201,">60",'Service Principals'!$S$2:$S$201,"<=90") -> 0
A43: 91-180 days | B43: =COUNTIFS('Service Principals'!$S$2:$S$201,">90",'Service Principals'!$S$2:$S$201,"<=180") -> 0
A44: 181-365 days | B44: =COUNTIFS('Service Principals'!$S$2:$S$201,">180",'Service Principals'!$S$2:$S$201,"<=365") -> 0
A45: Over 365 days | B45: =COUNTIF('Service Principals'!$S$2:$S$201,">365") -> 0
...

Sheet How to Use
B2: How to use this workbook
B4: Three identity tabs over a Microsoft Entra ID tenant, fed by three read-only PowerShell scripts. Everything the directory can tell you is imported; what remains is the governance context only a human can supply.
B6: Column colour code
B8: DARK BLUE - Graph import zone. Contiguous from column A. This is where you paste script output, and nothing in it is a formula.
B10: TEAL - lookups against the Azure Resource Map tab. GREY - calculated. Neither should ever be typed in or pasted over.
B12: BROWN - Conditional Access exclusion governance you enter. GREEN - ownership you enter. MID BLUE - other manual fields.
B14: Pale yellow row 2 on every tab is a worked example. Delete it before loading real data. Headers with a red corner marker carry a comment - hover for guidance.
B16: The refresh cycle
B18: 1. Build-CAExclusionMap.ps1 -> paste into 'CA Exclusion Map' at A2, columns A-I only.
B20: 2. Build-AzureResourceMap.ps1 -> paste into 'Azure Resource Map' at A2, columns A-O only.
B22: 3. Build-IdentityInventory.ps1 -> three CSVs, paste each into its tab at A2.
B24: On each map tab the final column is a formula that flags entries with no matching inventory row - never paste over it. Select the existing data and clear it before pasting a fresh snapshot rather than pasting on top, or stale rows will linger.
... B74: Entra retains sign-in logs for 30 days. Export to a Log Analytics workspace in Australia East if you need longer history for attestation evidence, and note the Region column where a managed identity processes personal information. Privacy Act advice should come from your own advisers.

Sheet Accounts
A1: Display Name | B1: User Principal Name | C1: Object ID | D1: Account Category | E1: User Type | F1: Identity Source | G1: Account Enabled? | H1: Created Date | I1: Last Interactive Sign-In | J1: Last Non-Interactive Sign-In | K1: MFA / Strong Auth Status | L1: Privileged Roles (Active) | M1: Privileged Roles (PIM Eligible) | N1: Licence Assigned | O1: Manager (Graph) | P1: Manager Email (Graph) | Q1: Days Since Sign-In | R1: Category Confirmed? | S1: Azure RBAC Roles | T1: Highest Azure Role | U1: Sub / MG Scoped? | V1: CA Excluded? | W1: Exclusion Mechanism | X1: Exclusion Group Name | Y1: Policies Excluded From | Z1: Exclusion Justification | AA1: Exclusion Approved By | AB1: Exclusion Approved Date | AC1: Exclusion Expiry Date | AD1: Exclusion Status | AE1: Compensating Controls | AF1: Owner Team | AG1: Owner Name (Confirmed) | AH1: Owner Email | AI1: Backup / Secondary Owner | AJ1: Cost Centre / App ID | AK1: Environment | AL1: Business Criticality | AM1: Last Reviewed | AN1: Reviewed By | AO1: Review Disposition | AP1: Next Review Due | AQ1: Review Status | AR1: Notes
A2: SVC Payroll Integration | B2: svc-payroll-int@contoso.com.au | C2: 8f1a2c34-5b6d-4e7f-9a0b-1c2d3e4f5a6b | D2: Service Account (inferred) | E2: Member | F2: Cloud-only | G2: Yes | H2: 44999 | J2: 46234 | K2: Not Registered | L2: None | M2: None | N2: Microsoft 365 E3 | O2: Priya Raman | P2: priya.raman@contoso.com.au | Q2: =IF(J2="","",TODAY()-J2) -> 5 | S2: =IFERROR(INDEX('Azure Resource Map'!$D$2:$D$2001,MATCH($C2,'Azure Resource Map'!$A$2:$A$2001,0)),"") | T2: =IFERROR(INDEX('Azure Resource Map'!$E$2:$E$2001,MATCH($C2,'Azure Resource Map'!$A$2:$A$2001,0)),"") | U2: =IFERROR(INDEX('Azure Resource Map'!$F$2:$F$2001,MATCH($C2,'Azure Resource Map'!$A$2:$A$2001,0)),"") | V2: =IF($C2="","",IF(ISNUMBER(MATCH($C2,'CA Exclusion Map'!$A$2:$A$2001,0)),"Yes","No")) -> Yes | W2: =IFERROR(INDEX('CA Exclusion Map'!$D$2:$D$2001,MATCH($C2,'CA Exclusion Map'!$A$2:$A$2001,0)),"") -> Group membership | X2: =IFERROR(INDEX('CA Exclusion Map'!$E$2:$E$2001,MATCH($C2,'CA Exclusion Map'!$A$2:$A$2001,0)),"") -> CA-Excl-ServiceAccounts | Y2: =IFERROR(INDEX('CA Exclusion Map'!$F$2:$F$2001,MATCH($C2,'CA Exclusion Map'!$A$2:$A$2001,0)),"") -> CA001-Require MFA All Users; CA003-Require Compliant Device | Z2: Non-interactive batch account for the Chris21 payroll integration; cannot complete MFA. | AA2: J. Nguyen (CISO) | AB2: 46063 | AC2: 46356 | AD2: =IF(V2="","",IF(V2<>"Yes","N/A",IF(AC2="","NO EXPIRY SET",IF(TODAY()>AC2,"EXPIRED",IF(AC2-TODAY()<=30,"Expiring Soon","Active"))))) -> Active | AE2: Named location lock (Sydney DC egress); password in Key Vault, 90-day rotation; SOC alerting. | AF2: People & Culture Systems | AG2: Priya Raman | AH2: priya.raman@contoso.com.au | AI2: Tom Fitzgerald | AJ2: CC-4820 | AK2: Production | AL2: Critical | AM2: 46188 | AN2: IAM Team | AO2: Convert to managed identity | AP2: =IF(AM2="","",AM2+90) -> 46278 | AQ2: =IF(C2="","",IF(AM2="","NOT REVIEWED",IF(TODAY()>AP2,"OVERDUE",IF(AP2-TODAY()<=14,"Due Soon","Current")))) -> Current | AR2: EXAMPLE ROW - delete before use.
Q3: =IF(J3="","",TODAY()-J3) | S3: =IFERROR(INDEX('Azure Resource Map'!$D$2:$D$2001,MATCH($C3,'Azure Resource Map'!$A$2:$A$2001,0)),"") | T3: =IFERROR(INDEX('Azure Resource Map'!$E$2:$E$2001,MATCH($C3,'Azure Resource Map'!$A$2:$A$2001,0)),"") | U3: =IFERROR(INDEX('Azure Resource Map'!$F$2:$F$2001,MATCH($C3,'Azure Resource Map'!$A$2:$A$2001,0)),"") | V3: =IF($C3="","",IF(ISNUMBER(MATCH($C3,'CA Exclusion Map'!$A$2:$A$2001,0)),"Yes","No")) | W3: =IFERROR(INDEX('CA Exclusion Map'!$D$2:$D$2001,MATCH($C3,'CA Exclusion Map'!$A$2:$A$2001,0)),"") | X3: =IFERROR(INDEX('CA Exclusion Map'!$E$2:$E$2001,MATCH($C3,'CA Exclusion Map'!$A$2:$A$2001,0)),"") | Y3: =IFERROR(INDEX('CA Exclusion Map'!$F$2:$F$2001,MATCH($C3,'CA Exclusion Map'!$A$2:$A$2001,0)),"") | AD3: =IF(V3="","",IF(V3<>"Yes","N/A",IF(AC3="","NO EXPIRY SET",IF(TODAY()>AC3,"EXPIRED",IF(AC3-TODAY()<=30,"Expiring Soon","Active"))))) | AP3: =IF(AM3="","",AM3+90) | AQ3: =IF(C3="","",IF(AM3="","NOT REVIEWED",IF(TODAY()>AP3,"OVERDUE",IF(AP3-TODAY()<=14,"Due Soon","Current"))))
Q4: =IF(J4="","",TODAY()-J4) | S4: =IFERROR(INDEX('Azure Resource Map'!$D$2:$D$2001,MATCH($C4,'Azure Resource Map'!$A$2:$A$2001,0)),"") | T4: =IFERROR(INDEX('Azure Resource Map'!$E$2:$E$2001,MATCH($C4,'Azure Resource Map'!$A$2:$A$2001,0)),"") | U4: =IFERROR(INDEX('Azure Resource Map'!$F$2:$F$2001,MATCH($C4,'Azure Resource Map'!$A$2:$A$2001,0)),"") | V4: =IF($C4="","",IF(ISNUMBER(MATCH($C4,'CA Exclusion Map'!$A$2:$A$2001,0)),"Yes","No")) | W4: =IFERROR(INDEX('CA Exclusion Map'!$D$2:$D$2001,MATCH($C4,'CA Exclusion Map'!$A$2:$A$2001,0)),"") | X4: =IFERROR(INDEX('CA Exclusion Map'!$E$2:$E$2001,MATCH($C4,'CA Exclusion Map'!$A$2:$A$2001,0)),"") | Y4: =IFERROR(INDEX('CA Exclusion Map'!$F$2:$F$2001,MATCH($C4,'CA Exclusion Map'!$A$2:$A$2001,0)),"") | AD4: =IF(V4="","",IF(V4<>"Yes","N/A",IF(AC4="","NO EXPIRY SET",IF(TODAY()>AC4,"EXPIRED",IF(AC4-TODAY()<=30,"Expiring Soon","Active"))))) | AP4: =IF(AM4="","",AM4+90) | AQ4: =IF(C4="","",IF(AM4="","NOT REVIEWED",IF(TODAY()>AP4,"OVERDUE",IF(AP4-TODAY()<=14,"Due Soon","Current"))))
Q5: =IF(J5="","",TODAY()-J5) | S5: =IFERROR(INDEX('Azure Resource Map'!$D$2:$D$2001,MATCH($C5,'Azure Resource Map'!$A$2:$A$2001,0)),"") | T5: =IFERROR(INDEX('Azure Resource Map'!$E$2:$E$2001,MATCH($C5,'Azure Resource Map'!$A$2:$A$2001,0)),"") | U5: =IFERROR(INDEX('Azure Resource Map'!$F$2:$F$2001,MATCH($C5,'Azure Resource Map'!$A$2:$A$2001,0)),"") | V5: =IF($C5="","",IF(ISNUMBER(MATCH($C5,'CA Exclusion Map'!$A$2:$A$2001,0)),"Yes","No")) | W5: =IFERROR(INDEX('CA Exclusion Map'!$D$2:$D$2001,MATCH($C5,'CA Exclusion Map'!$A$2:$A$2001,0)),"") | X5: =IFERROR(INDEX('CA Exclusion Map'!$E$2:$E$2001,MATCH($C5,'CA Exclusion Map'!$A$2:$A$2001,0)),"") | Y5: =IFERROR(INDEX('CA Exclusion Map'!$F$2:$F$2001,MATCH($C5,'CA Exclusion Map'!$A$2:$A$2001,0)),"") | AD5: =IF(V5="","",IF(V5<>"Yes","N/A",IF(AC5="","NO EXPIRY SET",IF(TODAY()>AC5,"EXPIRED",IF(AC5-TODAY()<=30,"Expiring Soon","Active"))))) | AP5: =IF(AM5="","",AM5+90) | AQ5: =IF(C5="","",IF(AM5="","NOT REVIEWED",IF(TODAY()>AP5,"OVERDUE",IF(AP5-TODAY()<=14,"Due Soon","Current"))))
Q6: =IF(J6="","",TODAY()-J6) | S6: =IFERROR(INDEX('Azure Resource Map'!$D$2:$D$2001,MATCH($C6,'Azure Resource Map'!$A$2:$A$2001,0)),"") | T6: =IFERROR(INDEX('Azure Resource Map'!$E$2:$E$2001,MATCH($C6,'Azure Resource Map'!$A$2:$A$2001,0)),"") | U6: =IFERROR(INDEX('Azure Resource Map'!$F$2:$F$2001,MATCH($C6,'Azure Resource Map'!$A$2:$A$2001,0)),"") | V6: =IF($C6="","",IF(ISNUMBER(MATCH($C6,'CA Exclusion Map'!$A$2:$A$2001,0)),"Yes","No")) | W6: =IFERROR(INDEX('CA Exclusion Map'!$D$2:$D$2001,MATCH($C6,'CA Exclusion Map'!$A$2:$A$2001,0)),"") | X6: =IFERROR(INDEX('CA Exclusion Map'!$E$2:$E$2001,MATCH($C6,'CA Exclusion Map'!$A$2:$A$2001,0)),"") | Y6: =IFERROR(INDEX('CA Exclusion Map'!$F$2:$F$2001,MATCH($C6,'CA Exclusion Map'!$A$2:$A$2001,0)),"") | AD6: =IF(V6="","",IF(V6<>"Yes","N/A",IF(AC6="","NO EXPIRY SET",IF(TODAY()>AC6,"EXPIRED",IF(AC6-TODAY()<=30,"Expiring Soon","Active"))))) | AP6: =IF(AM6="","",AM6+90) | AQ6: =IF(C6="","",IF(AM6="","NOT REVIEWED",IF(TODAY()>AP6,"OVERDUE",IF(AP6-TODAY()<=14,"Due Soon","Current"))))
Q7: =IF(J7="","",TODAY()-J7) | S7: =IFERROR(INDEX('Azure Resource Map'!$D$2:$D$2001,MATCH($C7,'Azure Resource Map'!$A$2:$A$2001,0)),"") | T7: =IFERROR(INDEX('Azure Resource Map'!$E$2:$E$2001,MATCH($C7,'Azure Resource Map'!$A$2:$A$2001,0)),"") | U7: =IFERROR(INDEX('Azure Resource Map'!$F$2:$F$2001,MATCH($C7,'Azure Resource Map'!$A$2:$A$2001,0)),"") | V7: =IF($C7="","",IF(ISNUMBER(MATCH($C7,'CA Exclusion Map'!$A$2:$A$2001,0)),"Yes","No")) | W7: =IFERROR(INDEX('CA Exclusion Map'!$D$2:$D$2001,MATCH($C7,'CA Exclusion Map'!$A$2:$A$2001,0)),"") | X7: =IFERROR(INDEX('CA Exclusion Map'!$E$2:$E$2001,MATCH($C7,'CA Exclusion Map'!$A$2:$A$2001,0)),"") | Y7: =IFERROR(INDEX('CA Exclusion Map'!$F$2:$F$2001,MATCH($C7,'CA Exclusion Map'!$A$2:$A$2001,0)),"") | AD7: =IF(V7="","",IF(V7<>"Yes","N/A",IF(AC7="","NO EXPIRY SET",IF(TODAY()>AC7,"EXPIRED",IF(AC7-TODAY()<=30,"Expiring Soon","Active"))))) | AP7: =IF(AM7="","",AM7+90) | AQ7: =IF(C7="","",IF(AM7="","NOT REVIEWED",IF(TODAY()>AP7,"OVERDUE",IF(AP7-TODAY()<=14,"Due Soon","Current"))))
Q8: =IF(J8="","",TODAY()-J8) | S8: =IFERROR(INDEX('Azure Resource Map'!$D$2:$D$2001,MATCH($C8,'Azure Resource Map'!$A$2:$A$2001,0)),"") | T8: =IFERROR(INDEX('Azure Resource Map'!$E$2:$E$2001,MATCH($C8,'Azure Resource Map'!$A$2:$A$2001,0)),"") | U8: =IFERROR(INDEX('Azure Resource Map'!$F$2:$F$2001,MATCH($C8,'Azure Resource Map'!$A$2:$A$2001,0)),"") | V8: =IF($C8="","",IF(ISNUMBER(MATCH($C8,'CA Exclusion Map'!$A$2:$A$2001,0)),"Yes","No")) | W8: =IFERROR(INDEX('CA Exclusion Map'!$D$2:$D$2001,MATCH($C8,'CA Exclusion Map'!$A$2:$A$2001,0)),"") | X8: =IFERROR(INDEX('CA Exclusion Map'!$E$2:$E$2001,MATCH($C8,'CA Exclusion Map'!$A$2:$A$2001,0)),"") | Y8: =IFERROR(INDEX('CA Exclusion Map'!$F$2:$F$2001,MATCH($C8,'CA Exclusion Map'!$A$2:$A$2001,0)),"") | AD8: =IF(V8="","",IF(V8<>"Yes","N/A",IF(AC8="","NO EXPIRY SET",IF(TODAY()>AC8,"EXPIRED",IF(AC8-TODAY()<=30,"Expiring Soon","Active"))))) | AP8: =IF(AM8="","",AM8+90) | AQ8: =IF(C8="","",IF(AM8="","NOT REVIEWED",IF(TODAY()>AP8,"OVERDUE",IF(AP8-TODAY()<=14,"Due Soon","Current"))))
Q9: =IF(J9="","",TODAY()-J9) | S9: =IFERROR(INDEX('Azure Resource Map'!$D$2:$D$2001,MATCH($C9,'Azure Resource Map'!$A$2:$A$2001,0)),"") | T9: =IFERROR(INDEX('Azure Resource Map'!$E$2:$E$2001,MATCH($C9,'Azure Resource Map'!$A$2:$A$2001,0)),"") | U9: =IFERROR(INDEX('Azure Resource Map'!$F$2:$F$2001,MATCH($C9,'Azure Resource Map'!$A$2:$A$2001,0)),"") | V9: =IF($C9="","",IF(ISNUMBER(MATCH($C9,'CA Exclusion Map'!$A$2:$A$2001,0)),"Yes","No")) | W9: =IFERROR(INDEX('CA Exclusion Map'!$D$2:$D$2001,MATCH($C9,'CA Exclusion Map'!$A$2:$A$2001,0)),"") | X9: =IFERROR(INDEX('CA Exclusion Map'!$E$2:$E$2001,MATCH($C9,'CA Exclusion Map'!$A$2:$A$2001,0)),"") | Y9: =IFERROR(INDEX('CA Exclusion Map'!$F$2:$F$2001,MATCH($C9,'CA Exclusion Map'!$A$2:$A$2001,0)),"") | AD9: =IF(V9="","",IF(V9<>"Yes","N/A",IF(AC9="","NO EXPIRY SET",IF(TODAY()>AC9,"EXPIRED",IF(AC9-TODAY()<=30,"Expiring Soon","Active"))))) | AP9: =IF(AM9="","",AM9+90) | AQ9: =IF(C9="","",IF(AM9="","NOT REVIEWED",IF(TODAY()>AP9,"OVERDUE",IF(AP9-TODAY()<=14,"Due Soon","Current"))))
Q10: =IF(J10="","",TODAY()-J10) | S10: =IFERROR(INDEX('Azure Resource Map'!$D$2:$D$2001,MATCH($C10,'Azure Resource Map'!$A$2:$A$2001,0)),"") | T10: =IFERROR(INDEX('Azure Resource Map'!$E$2:$E$2001,MATCH($C10,'Azure Resource Map'!$A$2:$A$2001,0)),"") | U10: =IFERROR(INDEX('Azure Resource Map'!$F$2:$F$2001,MATCH($C10,'Azure Resource Map'!$A$2:$A$2001,0)),"") | V10: =IF($C10="","",IF(ISNUMBER(MATCH($C10,'CA Exclusion Map'!$A$2:$A$2001,0)),"Yes","No")) | W10: =IFERROR(INDEX('CA Exclusion Map'!$D$2:$D$2001,MATCH($C10,'CA Exclusion Map'!$A$2:$A$2001,0)),"") | X10: =IFERROR(INDEX('CA Exclusion Map'!$E$2:$E$2001,MATCH($C10,'CA Exclusion Map'!$A$2:$A$2001,0)),"") | Y10: =IFERROR(INDEX('CA Exclusion Map'!$F$2:$F$2001,MATCH($C10,'CA Exclusion Map'!$A$2:$A$2001,0)),"") | AD10: =IF(V10="","",IF(V10<>"Yes","N/A",IF(AC10="","NO EXPIRY SET",IF(TODAY()>AC10,"EXPIRED",IF(AC10-TODAY()<=30,"Expiring Soon","Active"))))) | AP10: =IF(AM10="","",AM10+90) | AQ10: =IF(C10="","",IF(AM10="","NOT REVIEWED",IF(TODAY()>AP10,"OVERDUE",IF(AP10-TODAY()<=14,"Due Soon","Current"))))
Q11: =IF(J11="","",TODAY()-J11) | S11: =IFERROR(INDEX('Azure Resource Map'!$D$2:$D$2001,MATCH($C11,'Azure Resource Map'!$A$2:$A$2001,0)),"") | T11: =IFERROR(INDEX('Azure Resource Map'!$E$2:$E$2001,MATCH($C11,'Azure Resource Map'!$A$2:$A$2001,0)),"") | U11: =IFERROR(INDEX('Azure Resource Map'!$F$2:$F$2001,MATCH($C11,'Azure Resource Map'!$A$2:$A$2001,0)),"") | V11: =IF($C11="","",IF(ISNUMBER(MATCH($C11,'CA Exclusion Map'!$A$2:$A$2001,0)),"Yes","No")) | W11: =IFERROR(INDEX('CA Exclusion Map'!$D$2:$D$2001,MATCH($C11,'CA Exclusion Map'!$A$2:$A$2001,0)),"") | X11: =IFERROR(INDEX('CA Exclusion Map'!$E$2:$E$2001,MATCH($C11,'CA Exclusion Map'!$A$2:$A$2001,0)),"") | Y11: =IFERROR(INDEX('CA Exclusion Map'!$F$2:$F$2001,MATCH($C11,'CA Exclusion Map'!$A$2:$A$2001,0)),"") | AD11: =IF(V11="","",IF(V11<>"Yes","N/A",IF(AC11="","NO EXPIRY SET",IF(TODAY()>AC11,"EXPIRED",IF(AC11-TODAY()<=30,"Expiring Soon","Active"))))) | AP11: =IF(AM11="","",AM11+90) | AQ11: =IF(C11="","",IF(AM11="","NOT REVIEWED",IF(TODAY()>AP11,"OVERDUE",IF(AP11-TODAY()<=14,"Due Soon","Current"))))
Q12: =IF(J12="","",TODAY()-J12) | S12: =IFERROR(INDEX('Azure Resource Map'!$D$2:$D$2001,MATCH($C12,'Azure Resource Map'!$A$2:$A$2001,0)),"") | T12: =IFERROR(INDEX('Azure Resource Map'!$E$2:$E$2001,MATCH($C12,'Azure Resource Map'!$A$2:$A$2001,0)),"") | U12: =IFERROR(INDEX('Azure Resource Map'!$F$2:$F$2001,MATCH($C12,'Azure Resource Map'!$A$2:$A$2001,0)),"") | V12: =IF($C12="","",IF(ISNUMBER(MATCH($C12,'CA Exclusion Map'!$A$2:$A$2001,0)),"Yes","No")) | W12: =IFERROR(INDEX('CA Exclusion Map'!$D$2:$D$2001,MATCH($C12,'CA Exclusion Map'!$A$2:$A$2001,0)),"") | X12: =IFERROR(INDEX('CA Exclusion Map'!$E$2:$E$2001,MATCH($C12,'CA Exclusion Map'!$A$2:$A$2001,0)),"") | Y12: =IFERROR(INDEX('CA Exclusion Map'!$F$2:$F$2001,MATCH($C12,'CA Exclusion Map'!$A$2:$A$2001,0)),"") | AD12: =IF(V12="","",IF(V12<>"Yes","N/A",IF(AC12="","NO EXPIRY SET",IF(TODAY()>AC12,"EXPIRED",IF(AC12-TODAY()<=30,"Expiring Soon","Active"))))) | AP12: =IF(AM12="","",AM12+90) | AQ12: =IF(C12="","",IF(AM12="","NOT REVIEWED",IF(TODAY()>AP12,"OVERDUE",IF(AP12-TODAY()<=14,"Due Soon","Current"))))
Q13: =IF(J13="","",TODAY()-J13) | S13: =IFERROR(INDEX('Azure Resource Map'!$D$2:$D$2001,MATCH($C13,'Azure Resource Map'!$A$2:$A$2001,0)),"") | T13: =IFERROR(INDEX('Azure Resource Map'!$E$2:$E$2001,MATCH($C13,'Azure Resource Map'!$A$2:$A$2001,0)),"") | U13: =IFERROR(INDEX('Azure Resource Map'!$F$2:$F$2001,MATCH($C13,'Azure Resource Map'!$A$2:$A$2001,0)),"") | V13: =IF($C13="","",IF(ISNUMBER(MATCH($C13,'CA Exclusion Map'!$A$2:$A$2001,0)),"Yes","No")) | W13: =IFERROR(INDEX('CA Exclusion Map'!$D$2:$D$2001,MATCH($C13,'CA Exclusion Map'!$A$2:$A$2001,0)),"") | X13: =IFERROR(INDEX('CA Exclusion Map'!$E$2:$E$2001,MATCH($C13,'CA Exclusion Map'!$A$2:$A$2001,0)),"") | Y13: =IFERROR(INDEX('CA Exclusion Map'!$F$2:$F$2001,MATCH($C13,'CA Exclusion Map'!$A$2:$A$2001,0)),"") | AD13: =IF(V13="","",IF(V13<>"Yes","N/A",IF(AC13="","NO EXPIRY SET",IF(TODAY()>AC13,"EXPIRED",IF(AC13-TODAY()<=30,"Expiring Soon","Active"))))) | AP13: =IF(AM13="","",AM13+90) | AQ13: =IF(C13="","",IF(AM13="","NOT REVIEWED",IF(TODAY()>AP13,"OVERDUE",IF(AP13-TODAY()<=14,"Due Soon","Current"))))
Q14: =IF(J14="","",TODAY()-J14) | S14: =IFERROR(INDEX('Azure Resource Map'!$D$2:$D$2001,MATCH($C14,'Azure Resource Map'!$A$2:$A$2001,0)),"") | T14: =IFERROR(INDEX('Azure Resource Map'!$E$2:$E$2001,MATCH($C14,'Azure Resource Map'!$A$2:$A$2001,0)),"") | U14: =IFERROR(INDEX('Azure Resource Map'!$F$2:$F$2001,MATCH($C14,'Azure Resource Map'!$A$2:$A$2001,0)),"") | V14: =IF($C14="","",IF(ISNUMBER(MATCH($C14,'CA Exclusion Map'!$A$2:$A$2001,0)),"Yes","No")) | W14: =IFERROR(INDEX('CA Exclusion Map'!$D$2:$D$2001,MATCH($C14,'CA Exclusion Map'!$A$2:$A$2001,0)),"") | X14: =IFERROR(INDEX('CA Exclusion Map'!$E$2:$E$2001,MATCH($C14,'CA Exclusion Map'!$A$2:$A$2001,0)),"") | Y14: =IFERROR(INDEX('CA Exclusion Map'!$F$2:$F$2001,MATCH($C14,'CA Exclusion Map'!$A$2:$A$2001,0)),"") | AD14: =IF(V14="","",IF(V14<>"Yes","N/A",IF(AC14="","NO EXPIRY SET",IF(TODAY()>AC14,"EXPIRED",IF(AC14-TODAY()<=30,"Expiring Soon","Active"))))) | AP14: =IF(AM14="","",AM14+90) | AQ14: =IF(C14="","",IF(AM14="","NOT REVIEWED",IF(TODAY()>AP14,"OVERDUE",IF(AP14-TODAY()<=14,"Due Soon","Current"))))
... Q201: =IF(J201="","",TODAY()-J201) | S201: =IFERROR(INDEX('Azure Resource Map'!$D$2:$D$2001,MATCH($C201,'Azure Resource Map'!$A$2:$A$2001,0)),"") | T201: =IFERROR(INDEX('Azure Resource Map'!$E$2:$E$2001,MATCH($C201,'Azure Resource Map'!$A$2:$A$2001,0)),"") | U201: =IFERROR(INDEX('Azure Resource Map'!$F$2:$F$2001,MATCH($C201,'Azure Resource Map'!$A$2:$A$2001,0)),"") | V201: =IF($C201="","",IF(ISNUMBER(MATCH($C201,'CA Exclusion Map'!$A$2:$A$2001,0)),"Yes","No")) | W201: =IFERROR(INDEX('CA Exclusion Map'!$D$2:$D$2001,MATCH($C201,'CA Exclusion Map'!$A$2:$A$2001,0)),"") | X201: =IFERROR(INDEX('CA Exclusion Map'!$E$2:$E$2001,MATCH($C201,'CA Exclusion Map'!$A$2:$A$2001,0)),"") | Y201: =IFERROR(INDEX('CA Exclusion Map'!$F$2:$F$2001,MATCH($C201,'CA Exclusion Map'!$A$2:$A$2001,0)),"") | AD201: =IF(V201="","",IF(V201<>"Yes","N/A",IF(AC201="","NO EXPIRY SET",IF(TODAY()>AC201,"EXPIRED",IF(AC201-TODAY()<=30,"Expiring Soon","Active"))))) | AP201: =IF(AM201="","",AM201+90) | AQ201: =IF(C201="","",IF(AM201="","NOT REVIEWED",IF(TODAY()>AP201,"OVERDUE",IF(AP201-TODAY()<=14,"Due Soon","Current"))))

Sheet Service Principals
A1: Display Name | B1: Application (Client) ID | C1: Object ID (Enterprise App) | D1: App Origin | E1: Sign-in Audience | F1: Enabled? | G1: Created Date | H1: Last Sign-In | I1: Credential Type | J1: Next Credential Expiry | K1: Credential Count | L1: Highest Graph / API Permission | M1: Permission Risk | N1: Delegated Permissions | O1: Admin Consent Granted? | P1: Registered Owner (Graph) | Q1: Registered Owner Email | R1: Days Since Sign-In | S1: Days to Credential Expiry | T1: Credential Stored In | U1: Workload ID Premium Licensed? | V1: Azure RBAC Roles | W1: Highest Azure Role | X1: Sub / MG Scoped? | Y1: CA Excluded? | Z1: Exclusion Mechanism | AA1: Exclusion Group Name | AB1: Policies Excluded From | AC1: Exclusion Justification | AD1: Exclusion Approved By | AE1: Exclusion Approved Date | AF1: Exclusion Expiry Date | AG1: Exclusion Status | AH1: Compensating Controls | AI1: Owner Team | AJ1: Owner Name (Confirmed) | AK1: Owner Email | AL1: Backup / Secondary Owner | AM1: Cost Centre / App ID | AN1: Environment | AO1: Business Criticality | AP1: Last Reviewed | AQ1: Reviewed By | AR1: Review Disposition | AS1: Next Review Due | AT1: Review Status | AU1: Notes
A2: Invoice Reconciliation API | B2: c7d2e4f6-1a3b-4c5d-8e9f-0a1b2c3d4e5f | C2: 2b4d6f80-9c1e-4a3b-b5d7-e8f9a0b1c2d3 | D2: In-house | E2: Single tenant | F2: Yes | G2: 45506 | H2: 46237 | I2: Certificate | J2: 46277 | K2: 2 | L2: Files.ReadWrite.All | M2: High | N2: 0 | O2: Yes | P2: Daniel Okafor | Q2: daniel.okafor@contoso.com.au | R2: =IF(H2="","",TODAY()-H2) -> 2 | S2: =IF(J2="","",J2-TODAY()) -> 38 | T2: Azure Key Vault | U2: Yes | V2: =IFERROR(INDEX('Azure Resource Map'!$D$2:$D$2001,MATCH($C2,'Azure Resource Map'!$A$2:$A$2001,0)),"") -> Storage Blob Data Reader @ /subscriptions/.../rg-fin-prod-ause | W2: =IFERROR(INDEX('Azure Resource Map'!$E$2:$E$2001,MATCH($C2,'Azure Resource Map'!$A$2:$A$2001,0)),"") -> Storage Blob Data Reader | X2: =IFERROR(INDEX('Azure Resource Map'!$F$2:$F$2001,MATCH($C2,'Azure Resource Map'!$A$2:$A$2001,0)),"") -> No | Y2: =IF($C2="","",IF(ISNUMBER(MATCH($C2,'CA Exclusion Map'!$A$2:$A$2001,0)),"Yes","No")) -> No | Z2: =IFERROR(INDEX('CA Exclusion Map'!$D$2:$D$2001,MATCH($C2,'CA Exclusion Map'!$A$2:$A$2001,0)),"") | AA2: =IFERROR(INDEX('CA Exclusion Map'!$E$2:$E$2001,MATCH($C2,'CA Exclusion Map'!$A$2:$A$2001,0)),"") | AB2: =IFERROR(INDEX('CA Exclusion Map'!$F$2:$F$2001,MATCH($C2,'CA Exclusion Map'!$A$2:$A$2001,0)),"") | AG2: =IF(Y2="","",IF(Y2<>"Yes","N/A",IF(AF2="","NO EXPIRY SET",IF(TODAY()>AF2,"EXPIRED",IF(AF2-TODAY()<=30,"Expiring Soon","Active"))))) -> N/A | AH2: CA020 restricts sign-in to Australia East service tags. | AI2: Finance Systems | AJ2: Daniel Okafor | AK2: daniel.okafor@contoso.com.au | AL2: Finance Systems DL | AM2: CC-2210 | AN2: Production | AO2: High | AP2: 46162 | AQ2: Cyber Security Operations | AR2: Rotate credential | AS2: =IF(AP2="","",AP2+90) -> 46252 | AT2: =IF(C2="","",IF(AP2="","NOT REVIEWED",IF(TODAY()>AS2,"OVERDUE",IF(AS2-TODAY()<=14,"Due Soon","Current")))) -> Due Soon | AU2: EXAMPLE ROW - delete before use.
R3: =IF(H3="","",TODAY()-H3) | S3: =IF(J3="","",J3-TODAY()) | V3: =IFERROR(INDEX('Azure Resource Map'!$D$2:$D$2001,MATCH($C3,'Azure Resource Map'!$A$2:$A$2001,0)),"") | W3: =IFERROR(INDEX('Azure Resource Map'!$E$2:$E$2001,MATCH($C3,'Azure Resource Map'!$A$2:$A$2001,0)),"") | X3: =IFERROR(INDEX('Azure Resource Map'!$F$2:$F$2001,MATCH($C3,'Azure Resource Map'!$A$2:$A$2001,0)),"") | Y3: =IF($C3="","",IF(ISNUMBER(MATCH($C3,'CA Exclusion Map'!$A$2:$A$2001,0)),"Yes","No")) | Z3: =IFERROR(INDEX('CA Exclusion Map'!$D$2:$D$2001,MATCH($C3,'CA Exclusion Map'!$A$2:$A$2001,0)),"") | AA3: =IFERROR(INDEX('CA Exclusion Map'!$E$2:$E$2001,MATCH($C3,'CA Exclusion Map'!$A$2:$A$2001,0)),"") | AB3: =IFERROR(INDEX('CA Exclusion Map'!$F$2:$F$2001,MATCH($C3,'CA Exclusion Map'!$A$2:$A$2001,0)),"") | AG3: =IF(Y3="","",IF(Y3<>"Yes","N/A",IF(AF3="","NO EXPIRY SET",IF(TODAY()>AF3,"EXPIRED",IF(AF3-TODAY()<=30,"Expiring Soon","Active"))))) | AS3: =IF(AP3="","",AP3+90) | AT3: =IF(C3="","",IF(AP3="","NOT REVIEWED",IF(TODAY()>AS3,"OVERDUE",IF(AS3-TODAY()<=14,"Due Soon","Current"))))
R4: =IF(H4="","",TODAY()-H4) | S4: =IF(J4="","",J4-TODAY()) | V4: =IFERROR(INDEX('Azure Resource Map'!$D$2:$D$2001,MATCH($C4,'Azure Resource Map'!$A$2:$A$2001,0)),"") | W4: =IFERROR(INDEX('Azure Resource Map'!$E$2:$E$2001,MATCH($C4,'Azure Resource Map'!$A$2:$A$2001,0)),"") | X4: =IFERROR(INDEX('Azure Resource Map'!$F$2:$F$2001,MATCH($C4,'Azure Resource Map'!$A$2:$A$2001,0)),"") | Y4: =IF($C4="","",IF(ISNUMBER(MATCH($C4,'CA Exclusion Map'!$A$2:$A$2001,0)),"Yes","No")) | Z4: =IFERROR(INDEX('CA Exclusion Map'!$D$2:$D$2001,MATCH($C4,'CA Exclusion Map'!$A$2:$A$2001,0)),"") | AA4: =IFERROR(INDEX('CA Exclusion Map'!$E$2:$E$2001,MATCH($C4,'CA Exclusion Map'!$A$2:$A$2001,0)),"") | AB4: =IFERROR(INDEX('CA Exclusion Map'!$F$2:$F$2001,MATCH($C4,'CA Exclusion Map'!$A$2:$A$2001,0)),"") | AG4: =IF(Y4="","",IF(Y4<>"Yes","N/A",IF(AF4="","NO EXPIRY SET",IF(TODAY()>AF4,"EXPIRED",IF(AF4-TODAY()<=30,"Expiring Soon","Active"))))) | AS4: =IF(AP4="","",AP4+90) | AT4: =IF(C4="","",IF(AP4="","NOT REVIEWED",IF(TODAY()>AS4,"OVERDUE",IF(AS4-TODAY()<=14,"Due Soon","Current"))))
R5: =IF(H5="","",TODAY()-H5) | S5: =IF(J5="","",J5-TODAY()) | V5: =IFERROR(INDEX('Azure Resource Map'!$D$2:$D$2001,MATCH($C5,'Azure Resource Map'!$A$2:$A$2001,0)),"") | W5: =IFERROR(INDEX('Azure Resource Map'!$E$2:$E$2001,MATCH($C5,'Azure Resource Map'!$A$2:$A$2001,0)),"") | X5: =IFERROR(INDEX('Azure Resource Map'!$F$2:$F$2001,MATCH($C5,'Azure Resource Map'!$A$2:$A$2001,0)),"") | Y5: =IF($C5="","",IF(ISNUMBER(MATCH($C5,'CA Exclusion Map'!$A$2:$A$2001,0)),"Yes","No")) | Z5: =IFERROR(INDEX('CA Exclusion Map'!$D$2:$D$2001,MATCH($C5,'CA Exclusion Map'!$A$2:$A$2001,0)),"") | AA5: =IFERROR(INDEX('CA Exclusion Map'!$E$2:$E$2001,MATCH($C5,'CA Exclusion Map'!$A$2:$A$2001,0)),"") | AB5: =IFERROR(INDEX('CA Exclusion Map'!$F$2:$F$2001,MATCH($C5,'CA Exclusion Map'!$A$2:$A$2001,0)),"") | AG5: =IF(Y5="","",IF(Y5<>"Yes","N/A",IF(AF5="","NO EXPIRY SET",IF(TODAY()>AF5,"EXPIRED",IF(AF5-TODAY()<=30,"Expiring Soon","Active"))))) | AS5: =IF(AP5="","",AP5+90) | AT5: =IF(C5="","",IF(AP5="","NOT REVIEWED",IF(TODAY()>AS5,"OVERDUE",IF(AS5-TODAY()<=14,"Due Soon","Current"))))
R6: =IF(H6="","",TODAY()-H6) | S6: =IF(J6="","",J6-TODAY()) | V6: =IFERROR(INDEX('Azure Resource Map'!$D$2:$D$2001,MATCH($C6,'Azure Resource Map'!$A$2:$A$2001,0)),"") | W6: =IFERROR(INDEX('Azure Resource Map'!$E$2:$E$2001,MATCH($C6,'Azure Resource Map'!$A$2:$A$2001,0)),"") | X6: =IFERROR(INDEX('Azure Resource Map'!$F$2:$F$2001,MATCH($C6,'Azure Resource Map'!$A$2:$A$2001,0)),"") | Y6: =IF($C6="","",IF(ISNUMBER(MATCH($C6,'CA Exclusion Map'!$A$2:$A$2001,0)),"Yes","No")) | Z6: =IFERROR(INDEX('CA Exclusion Map'!$D$2:$D$2001,MATCH($C6,'CA Exclusion Map'!$A$2:$A$2001,0)),"") | AA6: =IFERROR(INDEX('CA Exclusion Map'!$E$2:$E$2001,MATCH($C6,'CA Exclusion Map'!$A$2:$A$2001,0)),"") | AB6: =IFERROR(INDEX('CA Exclusion Map'!$F$2:$F$2001,MATCH($C6,'CA Exclusion Map'!$A$2:$A$2001,0)),"") | AG6: =IF(Y6="","",IF(Y6<>"Yes","N/A",IF(AF6="","NO EXPIRY SET",IF(TODAY()>AF6,"EXPIRED",IF(AF6-TODAY()<=30,"Expiring Soon","Active"))))) | AS6: =IF(AP6="","",AP6+90) | AT6: =IF(C6="","",IF(AP6="","NOT REVIEWED",IF(TODAY()>AS6,"OVERDUE",IF(AS6-TODAY()<=14,"Due Soon","Current"))))
R7: =IF(H7="","",TODAY()-H7) | S7: =IF(J7="","",J7-TODAY()) | V7: =IFERROR(INDEX('Azure Resource Map'!$D$2:$D$2001,MATCH($C7,'Azure Resource Map'!$A$2:$A$2001,0)),"") | W7: =IFERROR(INDEX('Azure Resource Map'!$E$2:$E$2001,MATCH($C7,'Azure Resource Map'!$A$2:$A$2001,0)),"") | X7: =IFERROR(INDEX('Azure Resource Map'!$F$2:$F$2001,MATCH($C7,'Azure Resource Map'!$A$2:$A$2001,0)),"") | Y7: =IF($C7="","",IF(ISNUMBER(MATCH($C7,'CA Exclusion Map'!$A$2:$A$2001,0)),"Yes","No")) | Z7: =IFERROR(INDEX('CA Exclusion Map'!$D$2:$D$2001,MATCH($C7,'CA Exclusion Map'!$A$2:$A$2001,0)),"") | AA7: =IFERROR(INDEX('CA Exclusion Map'!$E$2:$E$2001,MATCH($C7,'CA Exclusion Map'!$A$2:$A$2001,0)),"") | AB7: =IFERROR(INDEX('CA Exclusion Map'!$F$2:$F$2001,MATCH($C7,'CA Exclusion Map'!$A$2:$A$2001,0)),"") | AG7: =IF(Y7="","",IF(Y7<>"Yes","N/A",IF(AF7="","NO EXPIRY SET",IF(TODAY()>AF7,"EXPIRED",IF(AF7-TODAY()<=30,"Expiring Soon","Active"))))) | AS7: =IF(AP7="","",AP7+90) | AT7: =IF(C7="","",IF(AP7="","NOT REVIEWED",IF(TODAY()>AS7,"OVERDUE",IF(AS7-TODAY()<=14,"Due Soon","Current"))))
R8: =IF(H8="","",TODAY()-H8) | S8: =IF(J8="","",J8-TODAY()) | V8: =IFERROR(INDEX('Azure Resource Map'!$D$2:$D$2001,MATCH($C8,'Azure Resource Map'!$A$2:$A$2001,0)),"") | W8: =IFERROR(INDEX('Azure Resource Map'!$E$2:$E$2001,MATCH($C8,'Azure Resource Map'!$A$2:$A$2001,0)),"") | X8: =IFERROR(INDEX('Azure Resource Map'!$F$2:$F$2001,MATCH($C8,'Azure Resource Map'!$A$2:$A$2001,0)),"") | Y8: =IF($C8="","",IF(ISNUMBER(MATCH($C8,'CA Exclusion Map'!$A$2:$A$2001,0)),"Yes","No")) | Z8: =IFERROR(INDEX('CA Exclusion Map'!$D$2:$D$2001,MATCH($C8,'CA Exclusion Map'!$A$2:$A$2001,0)),"") | AA8: =IFERROR(INDEX('CA Exclusion Map'!$E$2:$E$2001,MATCH($C8,'CA Exclusion Map'!$A$2:$A$2001,0)),"") | AB8: =IFERROR(INDEX('CA Exclusion Map'!$F$2:$F$2001,MATCH($C8,'CA Exclusion Map'!$A$2:$A$2001,0)),"") | AG8: =IF(Y8="","",IF(Y8<>"Yes","N/A",IF(AF8="","NO EXPIRY SET",IF(TODAY()>AF8,"EXPIRED",IF(AF8-TODAY()<=30,"Expiring Soon","Active"))))) | AS8: =IF(AP8="","",AP8+90) | AT8: =IF(C8="","",IF(AP8="","NOT REVIEWED",IF(TODAY()>AS8,"OVERDUE",IF(AS8-TODAY()<=14,"Due Soon","Current"))))
R9: =IF(H9="","",TODAY()-H9) | S9: =IF(J9="","",J9-TODAY()) | V9: =IFERROR(INDEX('Azure Resource Map'!$D$2:$D$2001,MATCH($C9,'Azure Resource Map'!$A$2:$A$2001,0)),"") | W9: =IFERROR(INDEX('Azure Resource Map'!$E$2:$E$2001,MATCH($C9,'Azure Resource Map'!$A$2:$A$2001,0)),"") | X9: =IFERROR(INDEX('Azure Resource Map'!$F$2:$F$2001,MATCH($C9,'Azure Resource Map'!$A$2:$A$2001,0)),"") | Y9: =IF($C9="","",IF(ISNUMBER(MATCH($C9,'CA Exclusion Map'!$A$2:$A$2001,0)),"Yes","No")) | Z9: =IFERROR(INDEX('CA Exclusion Map'!$D$2:$D$2001,MATCH($C9,'CA Exclusion Map'!$A$2:$A$2001,0)),"") | AA9: =IFERROR(INDEX('CA Exclusion Map'!$E$2:$E$2001,MATCH($C9,'CA Exclusion Map'!$A$2:$A$2001,0)),"") | AB9: =IFERROR(INDEX('CA Exclusion Map'!$F$2:$F$2001,MATCH($C9,'CA Exclusion Map'!$A$2:$A$2001,0)),"") | AG9: =IF(Y9="","",IF(Y9<>"Yes","N/A",IF(AF9="","NO EXPIRY SET",IF(TODAY()>AF9,"EXPIRED",IF(AF9-TODAY()<=30,"Expiring Soon","Active"))))) | AS9: =IF(AP9="","",AP9+90) | AT9: =IF(C9="","",IF(AP9="","NOT REVIEWED",IF(TODAY()>AS9,"OVERDUE",IF(AS9-TODAY()<=14,"Due Soon","Current"))))
R10: =IF(H10="","",TODAY()-H10) | S10: =IF(J10="","",J10-TODAY()) | V10: =IFERROR(INDEX('Azure Resource Map'!$D$2:$D$2001,MATCH($C10,'Azure Resource Map'!$A$2:$A$2001,0)),"") | W10: =IFERROR(INDEX('Azure Resource Map'!$E$2:$E$2001,MATCH($C10,'Azure Resource Map'!$A$2:$A$2001,0)),"") | X10: =IFERROR(INDEX('Azure Resource Map'!$F$2:$F$2001,MATCH($C10,'Azure Resource Map'!$A$2:$A$2001,0)),"") | Y10: =IF($C10="","",IF(ISNUMBER(MATCH($C10,'CA Exclusion Map'!$A$2:$A$2001,0)),"Yes","No")) | Z10: =IFERROR(INDEX('CA Exclusion Map'!$D$2:$D$2001,MATCH($C10,'CA Exclusion Map'!$A$2:$A$2001,0)),"") | AA10: =IFERROR(INDEX('CA Exclusion Map'!$E$2:$E$2001,MATCH($C10,'CA Exclusion Map'!$A$2:$A$2001,0)),"") | AB10: =IFERROR(INDEX('CA Exclusion Map'!$F$2:$F$2001,MATCH($C10,'CA Exclusion Map'!$A$2:$A$2001,0)),"") | AG10: =IF(Y10="","",IF(Y10<>"Yes","N/A",IF(AF10="","NO EXPIRY SET",IF(TODAY()>AF10,"EXPIRED",IF(AF10-TODAY()<=30,"Expiring Soon","Active"))))) | AS10: =IF(AP10="","",AP10+90) | AT10: =IF(C10="","",IF(AP10="","NOT REVIEWED",IF(TODAY()>AS10,"OVERDUE",IF(AS10-TODAY()<=14,"Due Soon","Current"))))
R11: =IF(H11="","",TODAY()-H11) | S11: =IF(J11="","",J11-TODAY()) | V11: =IFERROR(INDEX('Azure Resource Map'!$D$2:$D$2001,MATCH($C11,'Azure Resource Map'!$A$2:$A$2001,0)),"") | W11: =IFERROR(INDEX('Azure Resource Map'!$E$2:$E$2001,MATCH($C11,'Azure Resource Map'!$A$2:$A$2001,0)),"") | X11: =IFERROR(INDEX('Azure Resource Map'!$F$2:$F$2001,MATCH($C11,'Azure Resource Map'!$A$2:$A$2001,0)),"") | Y11: =IF($C11="","",IF(ISNUMBER(MATCH($C11,'CA Exclusion Map'!$A$2:$A$2001,0)),"Yes","No")) | Z11: =IFERROR(INDEX('CA Exclusion Map'!$D$2:$D$2001,MATCH($C11,'CA Exclusion Map'!$A$2:$A$2001,0)),"") | AA11: =IFERROR(INDEX('CA Exclusion Map'!$E$2:$E$2001,MATCH($C11,'CA Exclusion Map'!$A$2:$A$2001,0)),"") | AB11: =IFERROR(INDEX('CA Exclusion Map'!$F$2:$F$2001,MATCH($C11,'CA Exclusion Map'!$A$2:$A$2001,0)),"") | AG11: =IF(Y11="","",IF(Y11<>"Yes","N/A",IF(AF11="","NO EXPIRY SET",IF(TODAY()>AF11,"EXPIRED",IF(AF11-TODAY()<=30,"Expiring Soon","Active"))))) | AS11: =IF(AP11="","",AP11+90) | AT11: =IF(C11="","",IF(AP11="","NOT REVIEWED",IF(TODAY()>AS11,"OVERDUE",IF(AS11-TODAY()<=14,"Due Soon","Current"))))
R12: =IF(H12="","",TODAY()-H12) | S12: =IF(J12="","",J12-TODAY()) | V12: =IFERROR(INDEX('Azure Resource Map'!$D$2:$D$2001,MATCH($C12,'Azure Resource Map'!$A$2:$A$2001,0)),"") | W12: =IFERROR(INDEX('Azure Resource Map'!$E$2:$E$2001,MATCH($C12,'Azure Resource Map'!$A$2:$A$2001,0)),"") | X12: =IFERROR(INDEX('Azure Resource Map'!$F$2:$F$2001,MATCH($C12,'Azure Resource Map'!$A$2:$A$2001,0)),"") | Y12: =IF($C12="","",IF(ISNUMBER(MATCH($C12,'CA Exclusion Map'!$A$2:$A$2001,0)),"Yes","No")) | Z12: =IFERROR(INDEX('CA Exclusion Map'!$D$2:$D$2001,MATCH($C12,'CA Exclusion Map'!$A$2:$A$2001,0)),"") | AA12: =IFERROR(INDEX('CA Exclusion Map'!$E$2:$E$2001,MATCH($C12,'CA Exclusion Map'!$A$2:$A$2001,0)),"") | AB12: =IFERROR(INDEX('CA Exclusion Map'!$F$2:$F$2001,MATCH($C12,'CA Exclusion Map'!$A$2:$A$2001,0)),"") | AG12: =IF(Y12="","",IF(Y12<>"Yes","N/A",IF(AF12="","NO EXPIRY SET",IF(TODAY()>AF12,"EXPIRED",IF(AF12-TODAY()<=30,"Expiring Soon","Active"))))) | AS12: =IF(AP12="","",AP12+90) | AT12: =IF(C12="","",IF(AP12="","NOT REVIEWED",IF(TODAY()>AS12,"OVERDUE",IF(AS12-TODAY()<=14,"Due Soon","Current"))))
R13: =IF(H13="","",TODAY()-H13) | S13: =IF(J13="","",J13-TODAY()) | V13: =IFERROR(INDEX('Azure Resource Map'!$D$2:$D$2001,MATCH($C13,'Azure Resource Map'!$A$2:$A$2001,0)),"") | W13: =IFERROR(INDEX('Azure Resource Map'!$E$2:$E$2001,MATCH($C13,'Azure Resource Map'!$A$2:$A$2001,0)),"") | X13: =IFERROR(INDEX('Azure Resource Map'!$F$2:$F$2001,MATCH($C13,'Azure Resource Map'!$A$2:$A$2001,0)),"") | Y13: =IF($C13="","",IF(ISNUMBER(MATCH($C13,'CA Exclusion Map'!$A$2:$A$2001,0)),"Yes","No")) | Z13: =IFERROR(INDEX('CA Exclusion Map'!$D$2:$D$2001,MATCH($C13,'CA Exclusion Map'!$A$2:$A$2001,0)),"") | AA13: =IFERROR(INDEX('CA Exclusion Map'!$E$2:$E$2001,MATCH($C13,'CA Exclusion Map'!$A$2:$A$2001,0)),"") | AB13: =IFERROR(INDEX('CA Exclusion Map'!$F$2:$F$2001,MATCH($C13,'CA Exclusion Map'!$A$2:$A$2001,0)),"") | AG13: =IF(Y13="","",IF(Y13<>"Yes","N/A",IF(AF13="","NO EXPIRY SET",IF(TODAY()>AF13,"EXPIRED",IF(AF13-TODAY()<=30,"Expiring Soon","Active"))))) | AS13: =IF(AP13="","",AP13+90) | AT13: =IF(C13="","",IF(AP13="","NOT REVIEWED",IF(TODAY()>AS13,"OVERDUE",IF(AS13-TODAY()<=14,"Due Soon","Current"))))
R14: =IF(H14="","",TODAY()-H14) | S14: =IF(J14="","",J14-TODAY()) | V14: =IFERROR(INDEX('Azure Resource Map'!$D$2:$D$2001,MATCH($C14,'Azure Resource Map'!$A$2:$A$2001,0)),"") | W14: =IFERROR(INDEX('Azure Resource Map'!$E$2:$E$2001,MATCH($C14,'Azure Resource Map'!$A$2:$A$2001,0)),"") | X14: =IFERROR(INDEX('Azure Resource Map'!$F$2:$F$2001,MATCH($C14,'Azure Resource Map'!$A$2:$A$2001,0)),"") | Y14: =IF($C14="","",IF(ISNUMBER(MATCH($C14,'CA Exclusion Map'!$A$2:$A$2001,0)),"Yes","No")) | Z14: =IFERROR(INDEX('CA Exclusion Map'!$D$2:$D$2001,MATCH($C14,'CA Exclusion Map'!$A$2:$A$2001,0)),"") | AA14: =IFERROR(INDEX('CA Exclusion Map'!$E$2:$E$2001,MATCH($C14,'CA Exclusion Map'!$A$2:$A$2001,0)),"") | AB14: =IFERROR(INDEX('CA Exclusion Map'!$F$2:$F$2001,MATCH($C14,'CA Exclusion Map'!$A$2:$A$2001,0)),"") | AG14: =IF(Y14="","",IF(Y14<>"Yes","N/A",IF(AF14="","NO EXPIRY SET",IF(TODAY()>AF14,"EXPIRED",IF(AF14-TODAY()<=30,"Expiring Soon","Active"))))) | AS14: =IF(AP14="","",AP14+90) | AT14: =IF(C14="","",IF(AP14="","NOT REVIEWED",IF(TODAY()>AS14,"OVERDUE",IF(AS14-TODAY()<=14,"Due Soon","Current"))))
... R201: =IF(H201="","",TODAY()-H201) | S201: =IF(J201="","",J201-TODAY()) | V201: =IFERROR(INDEX('Azure Resource Map'!$D$2:$D$2001,MATCH($C201,'Azure Resource Map'!$A$2:$A$2001,0)),"") | W201: =IFERROR(INDEX('Azure Resource Map'!$E$2:$E$2001,MATCH($C201,'Azure Resource Map'!$A$2:$A$2001,0)),"") | X201: =IFERROR(INDEX('Azure Resource Map'!$F$2:$F$2001,MATCH($C201,'Azure Resource Map'!$A$2:$A$2001,0)),"") | Y201: =IF($C201="","",IF(ISNUMBER(MATCH($C201,'CA Exclusion Map'!$A$2:$A$2001,0)),"Yes","No")) | Z201: =IFERROR(INDEX('CA Exclusion Map'!$D$2:$D$2001,MATCH($C201,'CA Exclusion Map'!$A$2:$A$2001,0)),"") | AA201: =IFERROR(INDEX('CA Exclusion Map'!$E$2:$E$2001,MATCH($C201,'CA Exclusion Map'!$A$2:$A$2001,0)),"") | AB201: =IFERROR(INDEX('CA Exclusion Map'!$F$2:$F$2001,MATCH($C201,'CA Exclusion Map'!$A$2:$A$2001,0)),"") | AG201: =IF(Y201="","",IF(Y201<>"Yes","N/A",IF(AF201="","NO EXPIRY SET",IF(TODAY()>AF201,"EXPIRED",IF(AF201-TODAY()<=30,"Expiring Soon","Active"))))) | AS201: =IF(AP201="","",AP201+90) | AT201: =IF(C201="","",IF(AP201="","NOT REVIEWED",IF(TODAY()>AS201,"OVERDUE",IF(AS201-TODAY()<=14,"Due Soon","Current"))))

Sheet Managed Identities
A1: Display Name | B1: Client ID | C1: Object (Principal) ID | D1: Managed Identity Type | E1: Created Date | F1: Last Sign-In | G1: Graph / App Role Assignments | H1: Graph Permission Risk | I1: Days Since Sign-In | J1: Associated Azure Resource | K1: Resource Type | L1: Resource Group | M1: Subscription | N1: Region | O1: Azure Owner Tag | P1: Azure RBAC Roles | Q1: Highest Azure Role | R1: Sub / MG Scoped? | S1: Federated Credential Alternative? | T1: CA Excluded? | U1: Exclusion Mechanism | V1: Exclusion Group Name | W1: Policies Excluded From | X1: Exclusion Justification | Y1: Exclusion Approved By | Z1: Exclusion Approved Date | AA1: Exclusion Expiry Date | AB1: Exclusion Status | AC1: Compensating Controls | AD1: Owner Team | AE1: Owner Name (Confirmed) | AF1: Owner Email | AG1: Backup / Secondary Owner | AH1: Cost Centre / App ID | AI1: Environment | AJ1: Business Criticality | AK1: Last Reviewed | AL1: Reviewed By | AM1: Review Disposition | AN1: Next Review Due | AO1: Review Status | AP1: Notes
A2: mi-datafactory-prod-ause | B2: 5e6f7a8b-9c0d-4e1f-a2b3-c4d5e6f7a8b9 | C2: 9a8b7c6d-5e4f-4a3b-9c2d-1e0f9a8b7c6d | D2: User-assigned | E2: 45676 | F2: 46238 | G2: None | H2: Low | I2: =IF(F2="","",TODAY()-F2) -> 1 | J2: =IFERROR(INDEX('Azure Resource Map'!$H$2:$H$2001,MATCH($C2,'Azure Resource Map'!$A$2:$A$2001,0)),"") -> /subscriptions/a1b2.../resourceGroups/rg-analytics-prod-ause/providers/Microsoft.ManagedIdentity/userAssignedIdentities/mi-datafactory-prod-ause | K2: =IFERROR(INDEX('Azure Resource Map'!$I$2:$I$2001,MATCH($C2,'Azure Resource Map'!$A$2:$A$2001,0)),"") -> microsoft.managedidentity/userassignedidentities | L2: =IFERROR(INDEX('Azure Resource Map'!$J$2:$J$2001,MATCH($C2,'Azure Resource Map'!$A$2:$A$2001,0)),"") -> rg-analytics-prod-ause | M2: =IFERROR(INDEX('Azure Resource Map'!$K$2:$K$2001,MATCH($C2,'Azure Resource Map'!$A$2:$A$2001,0)),"") -> SUB-PROD-DATA | N2: =IFERROR(INDEX('Azure Resource Map'!$L$2:$L$2001,MATCH($C2,'Azure Resource Map'!$A$2:$A$2001,0)),"") -> australiaeast | O2: =IFERROR(INDEX('Azure Resource Map'!$M$2:$M$2001,MATCH($C2,'Azure Resource Map'!$A$2:$A$2001,0)),"") -> Aisha Karim | P2: =IFERROR(INDEX('Azure Resource Map'!$D$2:$D$2001,MATCH($C2,'Azure Resource Map'!$A$2:$A$2001,0)),"") -> Storage Blob Data Contributor @ st-datalake-prod; Key Vault Secrets User @ kv-data-prod | Q2: =IFERROR(INDEX('Azure Resource Map'!$E$2:$E$2001,MATCH($C2,'Azure Resource Map'!$A$2:$A$2001,0)),"") -> Storage Blob Data Contributor | R2: =IFERROR(INDEX('Azure Resource Map'!$F$2:$F$2001,MATCH($C2,'Azure Resource Map'!$A$2:$A$2001,0)),"") -> No | S2: No | T2: =IF($C2="","",IF(ISNUMBER(MATCH($C2,'CA Exclusion Map'!$A$2:$A$2001,0)),"Yes","No")) -> Yes | U2: =IFERROR(INDEX('CA Exclusion Map'!$D$2:$D$2001,MATCH($C2,'CA Exclusion Map'!$A$2:$A$2001,0)),"") -> Group membership | V2: =IFERROR(INDEX('CA Exclusion Map'!$E$2:$E$2001,MATCH($C2,'CA Exclusion Map'!$A$2:$A$2001,0)),"") -> CA-Excl-WorkloadIdentities | W2: =IFERROR(INDEX('CA Exclusion Map'!$F$2:$F$2001,MATCH($C2,'CA Exclusion Map'!$A$2:$A$2001,0)),"") -> CA015-Workload Identity Location Restriction | X2: Pipeline runs from an Azure-hosted integration runtime with dynamic egress IPs outside the approved named location. | Y2: M. Whitlam (Head of Cloud) | Z2: 46120 | AA2: 46303 | AB2: =IF(T2="","",IF(T2<>"Yes","N/A",IF(AA2="","NO EXPIRY SET",IF(TODAY()>AA2,"EXPIRED",IF(AA2-TODAY()<=30,"Expiring Soon","Active"))))) -> Active | AC2: Private endpoints only; no public network access; Defender for Cloud alerting. | AD2: Data & Analytics | AE2: Aisha Karim | AF2: aisha.karim@contoso.com.au | AG2: Cloud Platform Engineering | AH2: CC-6105 | AI2: Production | AJ2: High | AK2: 46204 | AL2: Cloud Platform Engineering | AM2: Retain | AN2: =IF(AK2="","",AK2+90) -> 46294 | AO2: =IF(C2="","",IF(AK2="","NOT REVIEWED",IF(TODAY()>AN2,"OVERDUE",IF(AN2-TODAY()<=14,"Due Soon","Current")))) -> Current | AP2: EXAMPLE ROW - delete before use.
I3: =IF(F3="","",TODAY()-F3) | J3: =IFERROR(INDEX('Azure Resource Map'!$H$2:$H$2001,MATCH($C3,'Azure Resource Map'!$A$2:$A$2001,0)),"") | K3: =IFERROR(INDEX('Azure Resource Map'!$I$2:$I$2001,MATCH($C3,'Azure Resource Map'!$A$2:$A$2001,0)),"") | L3: =IFERROR(INDEX('Azure Resource Map'!$J$2:$J$2001,MATCH($C3,'Azure Resource Map'!$A$2:$A$2001,0)),"") | M3: =IFERROR(INDEX('Azure Resource Map'!$K$2:$K$2001,MATCH($C3,'Azure Resource Map'!$A$2:$A$2001,0)),"") | N3: =IFERROR(INDEX('Azure Resource Map'!$L$2:$L$2001,MATCH($C3,'Azure Resource Map'!$A$2:$A$2001,0)),"") | O3: =IFERROR(INDEX('Azure Resource Map'!$M$2:$M$2001,MATCH($C3,'Azure Resource Map'!$A$2:$A$2001,0)),"") | P3: =IFERROR(INDEX('Azure Resource Map'!$D$2:$D$2001,MATCH($C3,'Azure Resource Map'!$A$2:$A$2001,0)),"") | Q3: =IFERROR(INDEX('Azure Resource Map'!$E$2:$E$2001,MATCH($C3,'Azure Resource Map'!$A$2:$A$2001,0)),"") | R3: =IFERROR(INDEX('Azure Resource Map'!$F$2:$F$2001,MATCH($C3,'Azure Resource Map'!$A$2:$A$2001,0)),"") | T3: =IF($C3="","",IF(ISNUMBER(MATCH($C3,'CA Exclusion Map'!$A$2:$A$2001,0)),"Yes","No")) | U3: =IFERROR(INDEX('CA Exclusion Map'!$D$2:$D$2001,MATCH($C3,'CA Exclusion Map'!$A$2:$A$2001,0)),"") | V3: =IFERROR(INDEX('CA Exclusion Map'!$E$2:$E$2001,MATCH($C3,'CA Exclusion Map'!$A$2:$A$2001,0)),"") | W3: =IFERROR(INDEX('CA Exclusion Map'!$F$2:$F$2001,MATCH($C3,'CA Exclusion Map'!$A$2:$A$2001,0)),"") | AB3: =IF(T3="","",IF(T3<>"Yes","N/A",IF(AA3="","NO EXPIRY SET",IF(TODAY()>AA3,"EXPIRED",IF(AA3-TODAY()<=30,"Expiring Soon","Active"))))) | AN3: =IF(AK3="","",AK3+90) | AO3: =IF(C3="","",IF(AK3="","NOT REVIEWED",IF(TODAY()>AN3,"OVERDUE",IF(AN3-TODAY()<=14,"Due Soon","Current"))))
I4: =IF(F4="","",TODAY()-F4) | J4: =IFERROR(INDEX('Azure Resource Map'!$H$2:$H$2001,MATCH($C4,'Azure Resource Map'!$A$2:$A$2001,0)),"") | K4: =IFERROR(INDEX('Azure Resource Map'!$I$2:$I$2001,MATCH($C4,'Azure Resource Map'!$A$2:$A$2001,0)),"") | L4: =IFERROR(INDEX('Azure Resource Map'!$J$2:$J$2001,MATCH($C4,'Azure Resource Map'!$A$2:$A$2001,0)),"") | M4: =IFERROR(INDEX('Azure Resource Map'!$K$2:$K$2001,MATCH($C4,'Azure Resource Map'!$A$2:$A$2001,0)),"") | N4: =IFERROR(INDEX('Azure Resource Map'!$L$2:$L$2001,MATCH($C4,'Azure Resource Map'!$A$2:$A$2001,0)),"") | O4: =IFERROR(INDEX('Azure Resource Map'!$M$2:$M$2001,MATCH($C4,'Azure Resource Map'!$A$2:$A$2001,0)),"") | P4: =IFERROR(INDEX('Azure Resource Map'!$D$2:$D$2001,MATCH($C4,'Azure Resource Map'!$A$2:$A$2001,0)),"") | Q4: =IFERROR(INDEX('Azure Resource Map'!$E$2:$E$2001,MATCH($C4,'Azure Resource Map'!$A$2:$A$2001,0)),"") | R4: =IFERROR(INDEX('Azure Resource Map'!$F$2:$F$2001,MATCH($C4,'Azure Resource Map'!$A$2:$A$2001,0)),"") | T4: =IF($C4="","",IF(ISNUMBER(MATCH($C4,'CA Exclusion Map'!$A$2:$A$2001,0)),"Yes","No")) | U4: =IFERROR(INDEX('CA Exclusion Map'!$D$2:$D$2001,MATCH($C4,'CA Exclusion Map'!$A$2:$A$2001,0)),"") | V4: =IFERROR(INDEX('CA Exclusion Map'!$E$2:$E$2001,MATCH($C4,'CA Exclusion Map'!$A$2:$A$2001,0)),"") | W4: =IFERROR(INDEX('CA Exclusion Map'!$F$2:$F$2001,MATCH($C4,'CA Exclusion Map'!$A$2:$A$2001,0)),"") | AB4: =IF(T4="","",IF(T4<>"Yes","N/A",IF(AA4="","NO EXPIRY SET",IF(TODAY()>AA4,"EXPIRED",IF(AA4-TODAY()<=30,"Expiring Soon","Active"))))) | AN4: =IF(AK4="","",AK4+90) | AO4: =IF(C4="","",IF(AK4="","NOT REVIEWED",IF(TODAY()>AN4,"OVERDUE",IF(AN4-TODAY()<=14,"Due Soon","Current"))))
I5: =IF(F5="","",TODAY()-F5) | J5: =IFERROR(INDEX('Azure Resource Map'!$H$2:$H$2001,MATCH($C5,'Azure Resource Map'!$A$2:$A$2001,0)),"") | K5: =IFERROR(INDEX('Azure Resource Map'!$I$2:$I$2001,MATCH($C5,'Azure Resource Map'!$A$2:$A$2001,0)),"") | L5: =IFERROR(INDEX('Azure Resource Map'!$J$2:$J$2001,MATCH($C5,'Azure Resource Map'!$A$2:$A$2001,0)),"") | M5: =IFERROR(INDEX('Azure Resource Map'!$K$2:$K$2001,MATCH($C5,'Azure Resource Map'!$A$2:$A$2001,0)),"") | N5: =IFERROR(INDEX('Azure Resource Map'!$L$2:$L$2001,MATCH($C5,'Azure Resource Map'!$A$2:$A$2001,0)),"") | O5: =IFERROR(INDEX('Azure Resource Map'!$M$2:$M$2001,MATCH($C5,'Azure Resource Map'!$A$2:$A$2001,0)),"") | P5: =IFERROR(INDEX('Azure Resource Map'!$D$2:$D$2001,MATCH($C5,'Azure Resource Map'!$A$2:$A$2001,0)),"") | Q5: =IFERROR(INDEX('Azure Resource Map'!$E$2:$E$2001,MATCH($C5,'Azure Resource Map'!$A$2:$A$2001,0)),"") | R5: =IFERROR(INDEX('Azure Resource Map'!$F$2:$F$2001,MATCH($C5,'Azure Resource Map'!$A$2:$A$2001,0)),"") | T5: =IF($C5="","",IF(ISNUMBER(MATCH($C5,'CA Exclusion Map'!$A$2:$A$2001,0)),"Yes","No")) | U5: =IFERROR(INDEX('CA Exclusion Map'!$D$2:$D$2001,MATCH($C5,'CA Exclusion Map'!$A$2:$A$2001,0)),"") | V5: =IFERROR(INDEX('CA Exclusion Map'!$E$2:$E$2001,MATCH($C5,'CA Exclusion Map'!$A$2:$A$2001,0)),"") | W5: =IFERROR(INDEX('CA Exclusion Map'!$F$2:$F$2001,MATCH($C5,'CA Exclusion Map'!$A$2:$A$2001,0)),"") | AB5: =IF(T5="","",IF(T5<>"Yes","N/A",IF(AA5="","NO EXPIRY SET",IF(TODAY()>AA5,"EXPIRED",IF(AA5-TODAY()<=30,"Expiring Soon","Active"))))) | AN5: =IF(AK5="","",AK5+90) | AO5: =IF(C5="","",IF(AK5="","NOT REVIEWED",IF(TODAY()>AN5,"OVERDUE",IF(AN5-TODAY()<=14,"Due Soon","Current"))))
